Workbook

Sheet Dashboard
B1: Laptop Market Dashboard · Technolife
B3: Top 100 listed laptops on technolife.com · prices in million Toman · all figures update with the filters below | Q3: Specs & value → | U3: Ratings & deals →
B4: FILTERS – pick a value from each dropdown (choose "All" to clear). Every chart and number on all three pages responds.
B5: Brand | G5: CPU maker | L5: GPU type | Q5: Price tier | V5: RAM class
B6: All | G6: All | L6: All | Q6: All | V6: All
B8: LAPTOPS SELECTED | G8: MEDIAN PRICE (M TOMAN) | L8: AVG RATING (WEIGHTED) | Q8: LAPTOPS ON DISCOUNT | V8: DEDICATED-GPU SHARE
B9: =Analysis!$B$5 -> 99 | G9: =Analysis!$B$7 -> 215.5 | L9: =Analysis!$B$12 -> 4.1783486 | Q9: =Analysis!$B$13 -> 0.080808081 | V9: =Analysis!$B$17 -> 0.33333333
B11: ="of "&SUM(Clean!$AD$2:$AD$101)&" laptops ("&COUNTA(Clean!$A$2:$A$101)&" crawled)" -> of 99 laptops (100 crawled) | G11: ="middle 50%: "&TEXT(Analysis!$B$9,"#,##0")&" – "&TEXT(Analysis!$B$10,"#,##0")&" M" -> middle 50%: 156 – 297 M | L11: =TEXT(Analysis!$B$16,"#,##0")&" reviews in total" -> 1,090 reviews in total | Q11: =Analysis!$B$14&" laptops · avg discount "&TEXT(Analysis!$B$15,"0.0%") -> 8 laptops · avg discount 4.4% | V11: ="RTX / dedicated graphics" -> RTX / dedicated graphics
B13: Key takeaways for the current selection
B14: =IF(Analysis!$B$5=0,"No laptops match these filters.","Largest brand: "&Analysis!I23&" with "&Analysis!J23&" laptops ("&TEXT(Analysis!J23/Analysis!$B$5,"0%")&" of the selection).") -> Largest brand: ASUS with 44 laptops (44% of the selection).
B15: =IF(Analysis!$B$6=0,"","Half of the laptops cost less than "&TEXT(Analysis!$B$7,"#,##0")&" M Toman; the average ("&TEXT(Analysis!$B$8,"#,##0")&" M) is "&IF(Analysis!$B$8>Analysis!$B$7,"pulled up by a few very expensive models.","close to the median, so prices are fairly balanced.")) -> Half of the laptops cost less than 216 M Toman; the average (238 M) is pulled up by a few very expensive models.
B16: =IF(OR(Analysis!B98=0,Analysis!B99=0),"Select ""All"" for GPU type to compare dedicated vs integrated graphics.","Dedicated-GPU laptops cost "&TEXT(Analysis!C98/Analysis!C99,"0.0")&"x as much as integrated-GPU laptops on average ("&TEXT(Analysis!C98,"#,##0")&" vs "&TEXT(Analysis!C99,"#,##0")&" M Toman).") -> Dedicated-GPU laptops cost 1.9x as much as integrated-GPU laptops on average (344 vs 185 M Toman).
B18: Brands: who sells what, and at which price
B36: Price structure of the market
B54: How to read: bars show the current filter selection. Price tiers and categories are defined on the Params sheet; every cleaning step is traceable Raw → Clean → Analysis → Dashboard.

Sheet Specs
B1: Specs & Value
B3: How hardware choices relate to price · prices in million Toman | Q3: Overview → | U3: Ratings & deals →
B4: ="Active filters · Brand: "&fBrand&" · CPU maker: "&fCPU&" · GPU: "&fGPU&" · Price tier: "&fTier&" · RAM: "&fRAM&" → "&Analysis!$B$5&" laptops selected (change filters on the Dashboard sheet)" -> Active filters · Brand: All · CPU maker: All · GPU: All · Price tier: All · RAM: All → 99 laptops selected (change filters on the Dashboard sheet)
B6: Memory and processor
B24: Graphics card and weight
B42: Multi-dimensional comparison: RAM class × storage class
B43: Average price (M Toman) – darker = more expensive | N43: Number of laptops in each cell (sample size)
B44: RAM \ Storage | E44: =Analysis!B$103 -> ≤ 256 GB | H44: =Analysis!C$103 -> 512 GB | K44: =Analysis!D$103 -> 1 TB + | N44: RAM \ Storage | Q44: =Analysis!B$103 -> ≤ 256 GB | T44: =Analysis!C$103 -> 512 GB | W44: =Analysis!D$103 -> 1 TB +
B45: =Analysis!A104 -> ≤ 8 GB | E45: =Analysis!B104 -> 117.9469 | H45: =Analysis!C104 -> 152.34889 | K45: =Analysis!D104 -> 121 | N45: =Analysis!A104 -> ≤ 8 GB | Q45: =Analysis!G104 -> 10 | T45: =Analysis!H104 -> 19 | W45: =Analysis!I104 -> 1
B46: =Analysis!A105 -> 12–16 GB | E46: =Analysis!B105 -> 131.4 | H46: =Analysis!C105 -> 241.09971 | K46: =Analysis!D105 -> 312.46842 | N46: =Analysis!A105 -> 12–16 GB | Q46: =Analysis!G105 -> 2 | T46: =Analysis!H105 -> 35 | W46: =Analysis!I105 -> 19
B47: =Analysis!A106 -> 20 GB + | E47: =Analysis!B106 -> – | H47: =Analysis!C106 -> 287.06667 | K47: =Analysis!D106 -> 404.625 | N47: =Analysis!A106 -> 20 GB + | Q47: =Analysis!G106 -> 0 | T47: =Analysis!H106 -> 3 | W47: =Analysis!I106 -> 8
B49: Cells show "–" when no laptop matches. Treat averages built on very few laptops (see the counts on the right) with caution.

Sheet Ratings
B1: Ratings & Deals
B3: What customers think and where the discounts are · rating = 0–5 stars from technolife.com | Q3: Overview → | U3: Specs & value →
B4: ="Active filters · Brand: "&fBrand&" · CPU maker: "&fCPU&" · GPU: "&fGPU&" · Price tier: "&fTier&" · RAM: "&fRAM&" → "&Analysis!$B$5&" laptops selected (change filters on the Dashboard sheet)" -> Active filters · Brand: All · CPU maker: All · GPU: All · Price tier: All · RAM: All → 99 laptops selected (change filters on the Dashboard sheet)
B6: AVG RATING (SIMPLE) | G6: AVG RATING (WEIGHTED) | L6: TOTAL REVIEWS | Q6: CORRELATION PRICE ↔ RATING | V6: AVG DISCOUNT
B7: =Analysis!$B$11 -> 4.479798 | G7: =Analysis!$B$12 -> 4.1783486 | L7: =Analysis!$B$16 -> 1090 | Q7: =Analysis!$B$19 -> 0.23904994 | V7: =Analysis!$B$15 -> 0.044143209
B9: ="average of laptop ratings" -> average of laptop ratings | G9: ="weighted by number of reviews" -> weighted by number of reviews | L9: ="over "&Analysis!$B$5&" laptops" -> over 99 laptops | Q9: ="Pearson r · no causal claim" -> Pearson r · no causal claim | V9: =Analysis!$B$14&" laptops discounted" -> 8 laptops discounted
B11: Best-rated laptops (Bayesian-weighted so a single 5-star review cannot win)
B12: Rank | D12: Laptop | O12: Brand | R12: Price (M) | U12: Rating | W12: Reviews
B13: =Analysis!A225 -> 1 | D13: =Analysis!D225 -> لپ تاپ اچ پی 15.6 اینچی مدل Victus 15 FA2082WM i5 13420H 32GB 1TB RTX4050 | O13: =Analysis!E225 -> HP | R13: =Analysis!F225 -> 310 | U13: =Analysis!G225 -> 5 | W13: =Analysis!H225 -> 7
B14: =Analysis!A226 -> 2 | D14: =Analysis!D226 -> لپ تاپ ایسوس 16 اینچی مدل ROG Strix G16 G615JMR i7 14650HX 16GB 1TB RTX 5060 | O14: =Analysis!E226 -> ASUS | R14: =Analysis!F226 -> 504 | U14: =Analysis!G226 -> 5 | W14: =Analysis!H226 -> 4
B15: =Analysis!A227 -> 3 | D15: =Analysis!D227 -> لپ تاپ 13 اینچی اپل مدل MacBook Neo A18 Pro 2026 8GB 256GB | O15: =Analysis!E227 -> Apple | R15: =Analysis!F227 -> 217.47 | U15: =Analysis!G227 -> 4.7 | W15: =Analysis!H227 -> 13
B16: =Analysis!A228 -> 4 | D16: =Analysis!D228 -> لپ تاپ ایسوس 15.6 اینچی مدل Vivobook 15 X1504VA i7 1355U 16GB 1TB | O16: =Analysis!E228 -> ASUS | R16: =Analysis!F228 -> 210.3 | U16: =Analysis!G228 -> 4.6 | W16: =Analysis!H228 -> 30
B17: =Analysis!A229 -> 5 | D17: =Analysis!D229 -> لپ تاپ اچ پی 15.6 اینچی مدل Victus 15 FA2082WM i5 13420H 32GB 512GB RTX4050 | O17: =Analysis!E229 -> HP | R17: =Analysis!F229 -> 314 | U17: =Analysis!G229 -> 5 | W17: =Analysis!H229 -> 2
B18: =Analysis!A230 -> 6 | D18: =Analysis!D230 -> لپ تاپ لنوو 15.3 اینچی مدل IdeaPad Slim 3 i5 13420H 8GB 512GB WUXGA Backlit | O18: =Analysis!E230 -> Lenovo | R18: =Analysis!F230 -> 160 | U18: =Analysis!G230 -> 5 | W18: =Analysis!H230 -> 2
B19: =Analysis!A231 -> 7 | D19: =Analysis!D231 -> لپ تاپ ام اس آی 15.6 اینچی مدل Cyborg 15 A13UC i7 13620H 16GB 1TB RTX 3050 | O19: =Analysis!E231 -> MSI | R19: =Analysis!F231 -> 272 | U19: =Analysis!G231 -> 5 | W19: =Analysis!H231 -> 2
B20: =Analysis!A232 -> 8 | D20: =Analysis!D232 -> لپ تاپ 16 اینچی ایسوس مدل TUF Gaming FX607VU CORE 5 210H 16GB 512GB RTX 4050 | O20: =Analysis!E232 -> ASUS | R20: =Analysis!F232 -> 312 | U20: =Analysis!G232 -> 4.6 | W20: =Analysis!H232 -> 22
B21: =Analysis!A233 -> 9 | D21: =Analysis!D233 -> لپ تاپ 15.6 اینچی لنوو مدل IdeaPad 1 15IJL7 Celeron N4500 8GB 256GB | O21: =Analysis!E233 -> Lenovo | R21: =Analysis!F233 -> 94.5 | U21: =Analysis!G233 -> 4.7 | W21: =Analysis!H233 -> 6
B22: =Analysis!A234 -> 10 | D22: =Analysis!D234 -> لپ تاپ ایسوس 16 اینچی مدل TUF Gaming F16 FX608JMR i7 14650HX 32GB 1TB RTX 5060 | O22: =Analysis!E234 -> ASUS | R22: =Analysis!F234 -> 495.5 | U22: =Analysis!G234 -> 4.6 | W22: =Analysis!H234 -> 9
B24: Ratings by brand and review volume
B42: Is a higher price associated with better ratings?
N43: ="Reading the plot"&CHAR(10)&CHAR(10)&"Pearson correlation between price and rating: "&IF(ISNUMBER(Analysis!$B$19),TEXT(Analysis!$B$19,"0.00"),"n/a")&CHAR(10)&CHAR(10)&"Values near 0 mean price tells us little about satisfaction; correlation does not imply that price causes better (or worse) ratings. Many laptops have only a few reviews, so single dots can be noisy." -> Reading the plot Pearson correlation between price and rating: 0.24 Values near 0 mean price tells us little about satisfaction; correlation does not imply that price causes better (or worse) ratings. Many laptops have only a few reviews, so single dots can be noisy.
B60: Biggest discounts in the current selection
B61: Rank | D61: Laptop | O61: Brand | R61: Now (M) | U61: Before (M) | W61: Off
B62: =IF(Analysis!D239="","",Analysis!A239) -> 1 | D62: =Analysis!D239 -> لپ تاپ ایسوس 16 اینچی مدل TUF Gaming F16 FX607VJB Core 5 210H 16GB 512GB RTX 3050 | O62: =Analysis!E239 -> ASUS | R62: =Analysis!F239 -> 277 | U62: =Analysis!G239 -> 312 | W62: =Analysis!H239 -> 0.11217949
B63: =IF(Analysis!D240="","",Analysis!A240) -> 2 | D63: =Analysis!D240 -> لپ تاپ 15.6 اینچی اچ پی مدل Victus 15 FB3093DX R7 7445HS 16GB 512GB RTX 4050 | O63: =Analysis!E240 -> HP | R63: =Analysis!F240 -> 299 | U63: =Analysis!G240 -> 325 | W63: =Analysis!H240 -> 0.08
B64: =IF(Analysis!D241="","",Analysis!A241) -> 3 | D64: =Analysis!D241 -> لپ تاپ 15.6 اینچی اچ پی مدل Victus 15 FA2013DX i5 13420H 8GB 512GB RTX 3050 | O64: =Analysis!E241 -> HP | R64: =Analysis!F241 -> 229 | U64: =Analysis!G241 -> 240 | W64: =Analysis!H241 -> 0.045833333
B65: =IF(Analysis!D242="","",Analysis!A242) -> 4 | D65: =Analysis!D242 -> لپ تاپ ام اس آی مدل VenturePro 15 A2RWEG Core 7 240H 16GB 1TB RTX 5050 | O65: =Analysis!E242 -> MSI | R65: =Analysis!F242 -> 289 | U65: =Analysis!G242 -> 300 | W65: =Analysis!H242 -> 0.036666667
B66: =IF(Analysis!D243="","",Analysis!A243) -> 5 | D66: =Analysis!D243 -> لپ تاپ اچ پی 15.6 اینچی مدل Victus 15 FA2082WM i5 13420H 16GB 512GB RTX4050 | O66: =Analysis!E243 -> HP | R66: =Analysis!F243 -> 275 | U66: =Analysis!G243 -> 285 | W66: =Analysis!H243 -> 0.035087719
B67: =IF(Analysis!D244="","",Analysis!A244) -> 6 | D67: =Analysis!D244 -> لپ تاپ اچ پی 16 اینچی مدل OmniBook 5 Next Gen AI 16 ag1070wm Ryzen AI 7 350 16GB 512GB | O67: =Analysis!E244 -> HP | R67: =Analysis!F244 -> 215 | U67: =Analysis!G244 -> 220 | W67: =Analysis!H244 -> 0.022727273
B68: =IF(Analysis!D245="","",Analysis!A245) -> 7 | D68: =Analysis!D245 -> لپ تاپ لنوو 15.6 اینچی مدل IdeaPad Slim 3 i3 1315U 8GB 256GB | O68: =Analysis!E245 -> Lenovo | R68: =Analysis!F245 -> 117.999 | U68: =Analysis!G245 -> 120 | W68: =Analysis!H245 -> 0.016675
B69: =IF(Analysis!D246="","",Analysis!A246) -> 8 | D69: =Analysis!D246 -> لپ تاپ لنوو 15.6 اینچی مدل IdeaPad Slim 3 i3 1315U 8GB 512GB | O69: =Analysis!E246 -> Lenovo | R69: =Analysis!F246 -> 125.499 | U69: =Analysis!G246 -> 126 | W69: =Analysis!H246 -> 0.0039761905
B70: =IF(Analysis!D247="","",Analysis!A247) | D70: =Analysis!D247 | O70: =Analysis!E247 | R70: =Analysis!F247 | U70: =Analysis!G247 | W70: =Analysis!H247
B71: =IF(Analysis!D248="","",Analysis!A248) | D71: =Analysis!D248 | O71: =Analysis!E248 | R71: =Analysis!F248 | U71: =Analysis!G248 | W71: =Analysis!H248
B73: Discount = (old price − current price) / old price, as shown by the store. Blank rows mean there are fewer than 10 discounted laptops in the selection.

Sheet Analysis
A1: Analysis tables (every figure respects the dashboard filters)
A3: A. KPIs
A4: metric | B4: value
A5: Laptops selected | B5: =SUM(Clean!$AE$2:$AE$101) -> 99
A6: Laptops selected with a price | B6: =SUM(Clean!$AF$2:$AF$101) -> 99
A7: Median price (M Toman) | B7: =IFERROR(MEDIAN(Clean!$AH$2:$AH$101),0) -> 215.5
A8: Average price (M Toman) | B8: =IFERROR(AVERAGEIFS(Clean!$G$2:$G$101,Clean!$AF$2:$AF$101,1),0) -> 237.77564
A9: Price Q1 (M Toman) | B9: =IFERROR(QUARTILE(Clean!$AH$2:$AH$101,1),0) -> 155.9
A10: Price Q3 (M Toman) | B10: =IFERROR(QUARTILE(Clean!$AH$2:$AH$101,3),0) -> 297
A11: Average rating (simple, rated laptops) | B11: =IFERROR(AVERAGEIFS(Clean!$K$2:$K$101,Clean!$AG$2:$AG$101,1),0) -> 4.479798
A12: Average rating (weighted by review count) | B12: =IFERROR(SUMPRODUCT(Clean!$AG$2:$AG$101,Clean!$K$2:$K$101,Clean!$L$2:$L$101)/SUMPRODUCT(Clean!$AG$2:$AG$101,Clean!$L$2:$L$101),0) -> 4.1783486
A13: Share of laptops with a discount | B13: =IFERROR(SUMIFS(Clean!$J$2:$J$101,Clean!$AE$2:$AE$101,1)/B5,0) -> 0.080808081
A14: Laptops with a discount | B14: =SUMIFS(Clean!$J$2:$J$101,Clean!$AE$2:$AE$101,1) -> 8
A15: Average discount (among discounted) | B15: =IFERROR(AVERAGEIFS(Clean!$I$2:$I$101,Clean!$AE$2:$AE$101,1,Clean!$J$2:$J$101,1),0) -> 0.044143209
A16: Total reviews | B16: =SUMIFS(Clean!$L$2:$L$101,Clean!$AE$2:$AE$101,1) -> 1090
A17: Dedicated-GPU share | B17: =IFERROR(COUNTIFS(Clean!$Z$2:$Z$101,"Dedicated",Clean!$AE$2:$AE$101,1)/B5,0) -> 0.33333333
A18: Laptops in rating/price scatter | B18: =SUM(Clean!$AQ$2:$AQ$101) -> 99
A19: Correlation price vs rating (Pearson r) | B19: =IF(B18<3,"n/a",IFERROR((B18*SUMPRODUCT(Clean!$AS$2:$AS$101,Clean!$AT$2:$AT$101)-SUM(Clean!$AS$2:$AS$101)*SUM(Clean!$AT$2:$AT$101))/SQRT((B18*SUMPRODUCT(Clean!$AS$2:$AS$101,Clean!$AS$2:$AS$101)-SUM(Clean!$AS$2:$AS$101)^2)*(B18*SUMPRODUCT(Clean!$AT$2:$AT$101,Clean!$AT$2:$AT$101)-SUM(Clean!$AT$2:$AT$101)^2)),"n/a")) -> 0.23904994
A21: B. Brands (unsorted list from data) and ranked by number of laptops
A22: # | B22: brand | C22: laptops | D22: avg price (M) | E22: w. rating | F22: sort key | H22: rank | I22: brand | J22: laptops | K22: avg price (M) | L22: w. rating
A23: 1 | B23: =Params!J6 -> Lenovo | C23: =COUNTIFS(Clean!$D$2:$D$101,B23,Clean!$AE$2:$AE$101,1) -> 28 | D23: =IFERROR(AVERAGEIFS(Clean!$G$2:$G$101,Clean!$D$2:$D$101,B23,Clean!$AF$2:$AF$101,1),0) -> 209.16064 | E23: =IFERROR(SUMPRODUCT((Clean!$D$2:$D$101=B23)*Clean!$AG$2:$AG$101*Clean!$K$2:$K$101*Clean!$L$2:$L$101)/SUMPRODUCT((Clean!$D$2:$D$101=B23)*Clean!$AG$2:$AG$101*Clean!$L$2:$L$101),0) -> 3.9961364 | F23: =C23+(9-A23)/1000 -> 28.008 | H23: 1 | I23: =INDEX($B$23:$B$30,MATCH(LARGE($F$23:$F$30,H23),$F$23:$F$30,0)) -> ASUS | J23: =INDEX($C$23:$C$30,MATCH(I23,$B$23:$B$30,0)) -> 44 | K23: =INDEX($D$23:$D$30,MATCH(I23,$B$23:$B$30,0)) -> 234.57273 | L23: =INDEX($E$23:$E$30,MATCH(I23,$B$23:$B$30,0)) -> 4.2680899
A24: 2 | B24: =Params!J7 -> MSI | C24: =COUNTIFS(Clean!$D$2:$D$101,B24,Clean!$AE$2:$AE$101,1) -> 5 | D24: =IFERROR(AVERAGEIFS(Clean!$G$2:$G$101,Clean!$D$2:$D$101,B24,Clean!$AF$2:$AF$101,1),0) -> 376.1 | E24: =IFERROR(SUMPRODUCT((Clean!$D$2:$D$101=B24)*Clean!$AG$2:$AG$101*Clean!$K$2:$K$101*Clean!$L$2:$L$101)/SUMPRODUCT((Clean!$D$2:$D$101=B24)*Clean!$AG$2:$AG$101*Clean!$L$2:$L$101),0) -> 4.6555556 | F24: =C24+(9-A24)/1000 -> 5.007 | H24: 2 | I24: =INDEX($B$23:$B$30,MATCH(LARGE($F$23:$F$30,H24),$F$23:$F$30,0)) -> Lenovo | J24: =INDEX($C$23:$C$30,MATCH(I24,$B$23:$B$30,0)) -> 28 | K24: =INDEX($D$23:$D$30,MATCH(I24,$B$23:$B$30,0)) -> 209.16064 | L24: =INDEX($E$23:$E$30,MATCH(I24,$B$23:$B$30,0)) -> 3.9961364
A25: 3 | B25: =Params!J8 -> ASUS | C25: =COUNTIFS(Clean!$D$2:$D$101,B25,Clean!$AE$2:$AE$101,1) -> 44 | D25: =IFERROR(AVERAGEIFS(Clean!$G$2:$G$101,Clean!$D$2:$D$101,B25,Clean!$AF$2:$AF$101,1),0) -> 234.57273 | E25: =IFERROR(SUMPRODUCT((Clean!$D$2:$D$101=B25)*Clean!$AG$2:$AG$101*Clean!$K$2:$K$101*Clean!$L$2:$L$101)/SUMPRODUCT((Clean!$D$2:$D$101=B25)*Clean!$AG$2:$AG$101*Clean!$L$2:$L$101),0) -> 4.2680899 | F25: =C25+(9-A25)/1000 -> 44.006 | H25: 3 | I25: =INDEX($B$23:$B$30,MATCH(LARGE($F$23:$F$30,H25),$F$23:$F$30,0)) -> HP | J25: =INDEX($C$23:$C$30,MATCH(I25,$B$23:$B$30,0)) -> 14 | K25: =INDEX($D$23:$D$30,MATCH(I25,$B$23:$B$30,0)) -> 250.89286 | L25: =INDEX($E$23:$E$30,MATCH(I25,$B$23:$B$30,0)) -> 4.3302857
A26: 4 | B26: =Params!J9 -> HP | C26: =COUNTIFS(Clean!$D$2:$D$101,B26,Clean!$AE$2:$AE$101,1) -> 14 | D26: =IFERROR(AVERAGEIFS(Clean!$G$2:$G$101,Clean!$D$2:$D$101,B26,Clean!$AF$2:$AF$101,1),0) -> 250.89286 | E26: =IFERROR(SUMPRODUCT((Clean!$D$2:$D$101=B26)*Clean!$AG$2:$AG$101*Clean!$K$2:$K$101*Clean!$L$2:$L$101)/SUMPRODUCT((Clean!$D$2:$D$101=B26)*Clean!$AG$2:$AG$101*Clean!$L$2:$L$101),0) -> 4.3302857 | F26: =C26+(9-A26)/1000 -> 14.005 | H26: 4 | I26: =INDEX($B$23:$B$30,MATCH(LARGE($F$23:$F$30,H26),$F$23:$F$30,0)) -> MSI | J26: =INDEX($C$23:$C$30,MATCH(I26,$B$23:$B$30,0)) -> 5 | K26: =INDEX($D$23:$D$30,MATCH(I26,$B$23:$B$30,0)) -> 376.1 | L26: =INDEX($E$23:$E$30,MATCH(I26,$B$23:$B$30,0)) -> 4.6555556
A27: 5 | B27: =Params!J10 -> Apple | C27: =COUNTIFS(Clean!$D$2:$D$101,B27,Clean!$AE$2:$AE$101,1) -> 4 | D27: =IFERROR(AVERAGEIFS(Clean!$G$2:$G$101,Clean!$D$2:$D$101,B27,Clean!$AF$2:$AF$101,1),0) -> 325.8475 | E27: =IFERROR(SUMPRODUCT((Clean!$D$2:$D$101=B27)*Clean!$AG$2:$AG$101*Clean!$K$2:$K$101*Clean!$L$2:$L$101)/SUMPRODUCT((Clean!$D$2:$D$101=B27)*Clean!$AG$2:$AG$101*Clean!$L$2:$L$101),0) -> 4.5941176 | F27: =C27+(9-A27)/1000 -> 4.004 | H27: 5 | I27: =INDEX($B$23:$B$30,MATCH(LARGE($F$23:$F$30,H27),$F$23:$F$30,0)) -> Apple | J27: =INDEX($C$23:$C$30,MATCH(I27,$B$23:$B$30,0)) -> 4 | K27: =INDEX($D$23:$D$30,MATCH(I27,$B$23:$B$30,0)) -> 325.8475 | L27: =INDEX($E$23:$E$30,MATCH(I27,$B$23:$B$30,0)) -> 4.5941176
A28: 6 | B28: =Params!J11 -> Samsung | C28: =COUNTIFS(Clean!$D$2:$D$101,B28,Clean!$AE$2:$AE$101,1) -> 0 | D28: =IFERROR(AVERAGEIFS(Clean!$G$2:$G$101,Clean!$D$2:$D$101,B28,Clean!$AF$2:$AF$101,1),0) -> 0 | E28: =IFERROR(SUMPRODUCT((Clean!$D$2:$D$101=B28)*Clean!$AG$2:$AG$101*Clean!$K$2:$K$101*Clean!$L$2:$L$101)/SUMPRODUCT((Clean!$D$2:$D$101=B28)*Clean!$AG$2:$AG$101*Clean!$L$2:$L$101),0) -> 0 | F28: =C28+(9-A28)/1000 -> 0.003 | H28: 6 | I28: =INDEX($B$23:$B$30,MATCH(LARGE($F$23:$F$30,H28),$F$23:$F$30,0)) -> Acer | J28: =INDEX($C$23:$C$30,MATCH(I28,$B$23:$B$30,0)) -> 2 | K28: =INDEX($D$23:$D$30,MATCH(I28,$B$23:$B$30,0)) -> 152.6 | L28: =INDEX($E$23:$E$30,MATCH(I28,$B$23:$B$30,0)) -> 5
A29: 7 | B29: =Params!J12 -> Acer | C29: =COUNTIFS(Clean!$D$2:$D$101,B29,Clean!$AE$2:$AE$101,1) -> 2 | D29: =IFERROR(AVERAGEIFS(Clean!$G$2:$G$101,Clean!$D$2:$D$101,B29,Clean!$AF$2:$AF$101,1),0) -> 152.6 | E29: =IFERROR(SUMPRODUCT((Clean!$D$2:$D$101=B29)*Clean!$AG$2:$AG$101*Clean!$K$2:$K$101*Clean!$L$2:$L$101)/SUMPRODUCT((Clean!$D$2:$D$101=B29)*Clean!$AG$2:$AG$101*Clean!$L$2:$L$101),0) -> 5 | F29: =C29+(9-A29)/1000 -> 2.002 | H29: 7 | I29: =INDEX($B$23:$B$30,MATCH(LARGE($F$23:$F$30,H29),$F$23:$F$30,0)) -> Dell | J29: =INDEX($C$23:$C$30,MATCH(I29,$B$23:$B$30,0)) -> 2 | K29: =INDEX($D$23:$D$30,MATCH(I29,$B$23:$B$30,0)) -> 180.25 | L29: =INDEX($E$23:$E$30,MATCH(I29,$B$23:$B$30,0)) -> 4.5
A30: 8 | B30: =Params!J13 -> Dell | C30: =COUNTIFS(Clean!$D$2:$D$101,B30,Clean!$AE$2:$AE$101,1) -> 2 | D30: =IFERROR(AVERAGEIFS(Clean!$G$2:$G$101,Clean!$D$2:$D$101,B30,Clean!$AF$2:$AF$101,1),0) -> 180.25 | E30: =IFERROR(SUMPRODUCT((Clean!$D$2:$D$101=B30)*Clean!$AG$2:$AG$101*Clean!$K$2:$K$101*Clean!$L$2:$L$101)/SUMPRODUCT((Clean!$D$2:$D$101=B30)*Clean!$AG$2:$AG$101*Clean!$L$2:$L$101),0) -> 4.5 | F30: =C30+(9-A30)/1000 -> 2.001 | H30: 8 | I30: =INDEX($B$23:$B$30,MATCH(LARGE($F$23:$F$30,H30),$F$23:$F$30,0)) -> Samsung | J30: =INDEX($C$23:$C$30,MATCH(I30,$B$23:$B$30,0)) -> 0 | K30: =INDEX($D$23:$D$30,MATCH(I30,$B$23:$B$30,0)) -> 0 | L30: =INDEX($E$23:$E$30,MATCH(I30,$B$23:$B$30,0)) -> 0
A33: C. Price distribution (M Toman)
A34: bin | B34: from | C34: to | D34: laptops
A35: =TEXT(B35,"0")&"–"&TEXT(C35,"0") -> 50–100 | B35: =p_bin0+0*p_binw -> 50 | C35: =B35+p_binw -> 100 | D35: =COUNTIFS(Clean!$G$2:$G$101,">="&B35,Clean!$G$2:$G$101,"<"&C35,Clean!$AF$2:$AF$101,1) -> 5
A36: =TEXT(B36,"0")&"–"&TEXT(C36,"0") -> 100–150 | B36: =p_bin0+1*p_binw -> 100 | C36: =B36+p_binw -> 150 | D36: =COUNTIFS(Clean!$G$2:$G$101,">="&B36,Clean!$G$2:$G$101,"<"&C36,Clean!$AF$2:$AF$101,1) -> 18
A37: =TEXT(B37,"0")&"–"&TEXT(C37,"0") -> 150–200 | B37: =p_bin0+2*p_binw -> 150 | C37: =B37+p_binw -> 200 | D37: =COUNTIFS(Clean!$G$2:$G$101,">="&B37,Clean!$G$2:$G$101,"<"&C37,Clean!$AF$2:$AF$101,1) -> 22
A38: =TEXT(B38,"0")&"–"&TEXT(C38,"0") -> 200–250 | B38: =p_bin0+3*p_binw -> 200 | C38: =B38+p_binw -> 250 | D38: =COUNTIFS(Clean!$G$2:$G$101,">="&B38,Clean!$G$2:$G$101,"<"&C38,Clean!$AF$2:$AF$101,1) -> 17
A39: =TEXT(B39,"0")&"–"&TEXT(C39,"0") -> 250–300 | B39: =p_bin0+4*p_binw -> 250 | C39: =B39+p_binw -> 300 | D39: =COUNTIFS(Clean!$G$2:$G$101,">="&B39,Clean!$G$2:$G$101,"<"&C39,Clean!$AF$2:$AF$101,1) -> 14
A40: =TEXT(B40,"0")&"–"&TEXT(C40,"0") -> 300–350 | B40: =p_bin0+5*p_binw -> 300 | C40: =B40+p_binw -> 350 | D40: =COUNTIFS(Clean!$G$2:$G$101,">="&B40,Clean!$G$2:$G$101,"<"&C40,Clean!$AF$2:$AF$101,1) -> 9
A41: =TEXT(B41,"0")&"–"&TEXT(C41,"0") -> 350–400 | B41: =p_bin0+6*p_binw -> 350 | C41: =B41+p_binw -> 400 | D41: =COUNTIFS(Clean!$G$2:$G$101,">="&B41,Clean!$G$2:$G$101,"<"&C41,Clean!$AF$2:$AF$101,1) -> 2
A42: =TEXT(B42,"0")&"–"&TEXT(C42,"0") -> 400–450 | B42: =p_bin0+7*p_binw -> 400 | C42: =B42+p_binw -> 450 | D42: =COUNTIFS(Clean!$G$2:$G$101,">="&B42,Clean!$G$2:$G$101,"<"&C42,Clean!$AF$2:$AF$101,1) -> 5
A43: =TEXT(B43,"0")&"–"&TEXT(C43,"0") -> 450–500 | B43: =p_bin0+8*p_binw -> 450 | C43: =B43+p_binw -> 500 | D43: =COUNTIFS(Clean!$G$2:$G$101,">="&B43,Clean!$G$2:$G$101,"<"&C43,Clean!$AF$2:$AF$101,1) -> 5
A44: =TEXT(B44,"0")&"+" -> 500+ | B44: =p_bin0+9*p_binw -> 500 | C44: 1000000 | D44: =COUNTIFS(Clean!$G$2:$G$101,">="&B44,Clean!$G$2:$G$101,"<"&C44,Clean!$AF$2:$AF$101,1) -> 2
...

Sheet Clean
A1: id | B1: name | C1: brand_raw | D1: brand | E1: status | F1: price (Toman) | G1: price (M Toman) | H1: old_price (Toman) | I1: discount % | J1: has_discount | K1: rating | L1: rating_count | M1: weighted rating (Bayesian) | N1: cpu | O1: cpu_maker | P1: cpu_family | Q1: ram_gb | R1: ram_class | S1: storage_part | T1: storage_gb | U1: storage_class | V1: screen_in | W1: weight_kg | X1: gpu | Y1: gpu_brand | Z1: gpu_type | AA1: gpu_model | AB1: price_tier | AC1: M Toman per GB RAM | AD1: is_laptop (name contains لپ تاپ) | AE1: in_filter | AF1: in_priced | AG1: in_rated | AH1: price_f (selected) | AI1: brand_seq | AJ1: family_seq | AK1: bayes_key | AL1: disc_key | AM1: sc_ded | AN1: cum_ded | AO1: sc_int | AP1: cum_int | AQ1: sc_rate | AR1: cum_rate | AS1: rx (price if scatter) | AT1: ry (rating if scatter) | AU1: data issues found
A2: =Raw!A2 -> 60492 | B2: =Raw!B2 -> لپ تاپ لنوو 15.6 اینچی مدل IdeaPad Slim 3 i3 1315U 8GB 512GB | C2: =LOWER(TRIM(Raw!C2)) -> lenovo | D2: =IFERROR(INDEX(Params!$B$5:$B$13,MATCH(C2,Params!$A$5:$A$13,0)),PROPER(C2)) -> Lenovo | E2: =IF(Raw!F2,"Available","Out of stock") -> Available | F2: =IF(Raw!D2="","",Raw!D2) -> 125499000 | G2: =IF(ISNUMBER(F2),F2/1000000,"") -> 125.499 | H2: =IF(Raw!E2="","",Raw!E2) -> 126000000 | I2: =IF(AND(ISNUMBER(H2),ISNUMBER(F2)),IF(H2>F2,(H2-F2)/H2,0),0) -> 0.0039761905 | J2: =IF(I2>0,1,0) -> 1 | K2: =Raw!G2 -> 4.2 | L2: =Raw!H2 -> 45 | M2: =IF(L2>0,(L2*K2+p_m*p_c)/(L2+p_m),"") -> 4.25 | N2: =IF(Raw!I2="","",TRIM(Raw!I2)) -> Core i3 1315U | O2: =IF(N2="","Unknown",IF(LEFT(N2,5)="Apple","Apple",IF(LEFT(N2,5)="Ryzen","AMD","Intel"))) -> Intel | P2: =IF(N2="","Unknown",IF(LEFT(N2,5)="Apple","Apple Silicon",IF(LEFT(N2,8)="Ryzen AI","Ryzen AI",TRIM(LEFT(N2,7))))) -> Core i3 | Q2: =IFERROR(VALUE(LEFT(Raw!J2,FIND(" ",Raw!J2)-1)),"") -> 8 | R2: =IF(NOT(ISNUMBER(Q2)),"Unknown",IF(Q2<=8,"≤ 8 GB",IF(Q2<=16,"12–16 GB","20 GB +"))) -> ≤ 8 GB | S2: =IF(Raw!K2="","",IF(ISNUMBER(FIND(" و ",Raw!K2)),TRIM(MID(Raw!K2,FIND(" و ",Raw!K2)+3,100)),TRIM(Raw!K2))) -> 512 گیگابایت | T2: =IF(S2="","",IFERROR(IFERROR(VALUE(LEFT(S2,FIND(" ",S2)-1)),VALUE(LEFT(S2,LEN(S2)-2)))*IF(OR(ISNUMBER(SEARCH("ترابایت",S2)),ISNUMBER(SEARCH("TB",S2))),1024,1),"")) -> 512 | U2: =IF(NOT(ISNUMBER(T2)),"Unknown",IF(T2<=256,"≤ 256 GB",IF(T2<=512,"512 GB","1 TB +"))) -> 512 GB | V2: =IFERROR(VALUE(SUBSTITUTE(LEFT(Raw!L2,FIND(" ",Raw!L2)-1),".",MID(1/2,2,1))),"") -> 15.6 | W2: =IFERROR(VALUE(SUBSTITUTE(LEFT(Raw!N2,FIND(" ",Raw!N2)-1),".",MID(1/2,2,1))),"") -> 1.6 | X2: =IF(Raw!M2="","",TRIM(Raw!M2)) -> Intel UHD Graphics | Y2: =IF(X2="","Unknown",IF(ISNUMBER(SEARCH("nvidia",X2)),"NVIDIA",IF(ISNUMBER(SEARCH("amd",X2)),"AMD",IF(ISNUMBER(SEARCH("apple",X2)),"Apple",IF(ISNUMBER(SEARCH("intel",X2)),"Intel","Other"))))) -> Intel | Z2: =IF(X2="","Unknown",IF(ISNUMBER(SEARCH("RTX",X2))+ISNUMBER(SEARCH("GTX",X2))+ISNUMBER(SEARCH("nvidia",X2))+ISNUMBER(SEARCH("Radeon RX",X2))>0,"Dedicated","Integrated")) -> Integrated | AA2: =IF(ISNUMBER(SEARCH("RTX",X2)),TRIM(MID(X2,SEARCH("RTX",X2),8)),IF(X2="","Unknown",IF(Z2="Dedicated","Dedicated (model n/a)","Integrated"))) -> Integrated | AB2: =IF(ISNUMBER(G2),INDEX(Params!$E$5:$E$9,MATCH(G2,Params!$D$5:$D$9,1)),"Unknown") -> 100–200 M | AC2: =IF(AND(ISNUMBER(G2),ISNUMBER(Q2)),IF(Q2>0,G2/Q2,""),"") -> 15.687375 | AD2: =IF(OR(p_excl=0,ISNUMBER(SEARCH("لپ",B2))),1,0) -> 1 | AE2: =IF(AND(AD2=1,OR(fBrand="All",D2=fBrand),OR(fCPU="All",O2=fCPU),OR(fGPU="All",Z2=fGPU),OR(fTier="All",AB2=fTier),OR(fRAM="All",R2=fRAM)),1,0) -> 1 | AF2: =IF(AND(AE2=1,ISNUMBER(G2)),1,0) -> 1 | AG2: =IF(AND(AE2=1,L2>0),1,0) -> 1 | AH2: =IF(AF2=1,G2,"") -> 125.499 | AI2: =IF(COUNTIF($D$2:D2,D2)=1,MAX($AI$1:AI1)+1,"") -> 1 | AJ2: =IF(COUNTIF($P$2:P2,P2)=1,MAX($AJ$1:AJ1)+1,"") -> 1 | AK2: =IF(AG2=1,M2+ROW()/1000000000,"") -> 4.25 | AL2: =IF(AND(AE2=1,I2>0),I2+ROW()/1000000000,"") -> 0.0039761925 | AM2: =IF(AND(AF2=1,ISNUMBER(W2),Z2="Dedicated"),1,0) -> 0 | AN2: =SUM($AM$2:AM2) -> 0 | AO2: =IF(AND(AF2=1,ISNUMBER(W2),Z2<>"Dedicated"),1,0) -> 1 | AP2: =SUM($AO$2:AO2) -> 1 | AQ2: =IF(AND(AF2=1,AG2=1),1,0) -> 1 | AR2: =SUM($AQ$2:AQ2) -> 1 | AS2: =IF(AQ2=1,G2,0) -> 125.499 | AT2: =IF(AQ2=1,K2,0) -> 4.2 | AU2: =TRIM(IF(Raw!N2="","weight missing; ","")&IF(Raw!K2="","storage missing; ","")&IF(ISNUMBER(FIND(" و ",Raw!K2)),"dual storage - SSD part used; ","")&IF(ISNUMBER(SEARCH("TB",Raw!K2)),"storage written as TB; ","")&IF(Raw!I2="","cpu missing; ","")&IF(Raw!M2="","gpu missing; ","")&IF(Raw!J2="","ram missing; ","")&IF(Raw!L2="","screen missing; ",""))
A3: =Raw!A3 -> 511107 | B3: =Raw!B3 -> لپ تاپ ام اس آی 15.6 اینچی مدل Cyborg 15 A13UC i7 13620H 16GB 1TB RTX 3050 | C3: =LOWER(TRIM(Raw!C3)) -> msi | D3: =IFERROR(INDEX(Params!$B$5:$B$13,MATCH(C3,Params!$A$5:$A$13,0)),PROPER(C3)) -> MSI | E3: =IF(Raw!F3,"Available","Out of stock") -> Available | F3: =IF(Raw!D3="","",Raw!D3) -> 272000000 | G3: =IF(ISNUMBER(F3),F3/1000000,"") -> 272 | H3: =IF(Raw!E3="","",Raw!E3) | I3: =IF(AND(ISNUMBER(H3),ISNUMBER(F3)),IF(H3>F3,(H3-F3)/H3,0),0) -> 0 | J3: =IF(I3>0,1,0) -> 0 | K3: =Raw!G3 -> 5 | L3: =Raw!H3 -> 2 | M3: =IF(L3>0,(L3*K3+p_m*p_c)/(L3+p_m),"") -> 4.5625 | N3: =IF(Raw!I3="","",TRIM(Raw!I3)) -> Core i7 13620H | O3: =IF(N3="","Unknown",IF(LEFT(N3,5)="Apple","Apple",IF(LEFT(N3,5)="Ryzen","AMD","Intel"))) -> Intel | P3: =IF(N3="","Unknown",IF(LEFT(N3,5)="Apple","Apple Silicon",IF(LEFT(N3,8)="Ryzen AI","Ryzen AI",TRIM(LEFT(N3,7))))) -> Core i7 | Q3: =IFERROR(VALUE(LEFT(Raw!J3,FIND(" ",Raw!J3)-1)),"") -> 16 | R3: =IF(NOT(ISNUMBER(Q3)),"Unknown",IF(Q3<=8,"≤ 8 GB",IF(Q3<=16,"12–16 GB","20 GB +"))) -> 12–16 GB | S3: =IF(Raw!K3="","",IF(ISNUMBER(FIND(" و ",Raw!K3)),TRIM(MID(Raw!K3,FIND(" و ",Raw!K3)+3,100)),TRIM(Raw!K3))) -> 1 ترابایت | T3: =IF(S3="","",IFERROR(IFERROR(VALUE(LEFT(S3,FIND(" ",S3)-1)),VALUE(LEFT(S3,LEN(S3)-2)))*IF(OR(ISNUMBER(SEARCH("ترابایت",S3)),ISNUMBER(SEARCH("TB",S3))),1024,1),"")) -> 1024 | U3: =IF(NOT(ISNUMBER(T3)),"Unknown",IF(T3<=256,"≤ 256 GB",IF(T3<=512,"512 GB","1 TB +"))) -> 1 TB + | V3: =IFERROR(VALUE(SUBSTITUTE(LEFT(Raw!L3,FIND(" ",Raw!L3)-1),".",MID(1/2,2,1))),"") -> 15.6 | W3: =IFERROR(VALUE(SUBSTITUTE(LEFT(Raw!N3,FIND(" ",Raw!N3)-1),".",MID(1/2,2,1))),"") -> 1.98 | X3: =IF(Raw!M3="","",TRIM(Raw!M3)) -> NVIDIA GeForce RTX 3050 | Y3: =IF(X3="","Unknown",IF(ISNUMBER(SEARCH("nvidia",X3)),"NVIDIA",IF(ISNUMBER(SEARCH("amd",X3)),"AMD",IF(ISNUMBER(SEARCH("apple",X3)),"Apple",IF(ISNUMBER(SEARCH("intel",X3)),"Intel","Other"))))) -> NVIDIA | Z3: =IF(X3="","Unknown",IF(ISNUMBER(SEARCH("RTX",X3))+ISNUMBER(SEARCH("GTX",X3))+ISNUMBER(SEARCH("nvidia",X3))+ISNUMBER(SEARCH("Radeon RX",X3))>0,"Dedicated","Integrated")) -> Dedicated | AA3: =IF(ISNUMBER(SEARCH("RTX",X3)),TRIM(MID(X3,SEARCH("RTX",X3),8)),IF(X3="","Unknown",IF(Z3="Dedicated","Dedicated (model n/a)","Integrated"))) -> RTX 3050 | AB3: =IF(ISNUMBER(G3),INDEX(Params!$E$5:$E$9,MATCH(G3,Params!$D$5:$D$9,1)),"Unknown") -> 200–300 M | AC3: =IF(AND(ISNUMBER(G3),ISNUMBER(Q3)),IF(Q3>0,G3/Q3,""),"") -> 17 | AD3: =IF(OR(p_excl=0,ISNUMBER(SEARCH("لپ",B3))),1,0) -> 1 | AE3: =IF(AND(AD3=1,OR(fBrand="All",D3=fBrand),OR(fCPU="All",O3=fCPU),OR(fGPU="All",Z3=fGPU),OR(fTier="All",AB3=fTier),OR(fRAM="All",R3=fRAM)),1,0) -> 1 | AF3: =IF(AND(AE3=1,ISNUMBER(G3)),1,0) -> 1 | AG3: =IF(AND(AE3=1,L3>0),1,0) -> 1 | AH3: =IF(AF3=1,G3,"") -> 272 | AI3: =IF(COUNTIF($D$2:D3,D3)=1,MAX($AI$1:AI2)+1,"") -> 2 | AJ3: =IF(COUNTIF($P$2:P3,P3)=1,MAX($AJ$1:AJ2)+1,"") -> 2 | AK3: =IF(AG3=1,M3+ROW()/1000000000,"") -> 4.5625 | AL3: =IF(AND(AE3=1,I3>0),I3+ROW()/1000000000,"") | AM3: =IF(AND(AF3=1,ISNUMBER(W3),Z3="Dedicated"),1,0) -> 1 | AN3: =SUM($AM$2:AM3) -> 1 | AO3: =IF(AND(AF3=1,ISNUMBER(W3),Z3<>"Dedicated"),1,0) -> 0 | AP3: =SUM($AO$2:AO3) -> 1 | AQ3: =IF(AND(AF3=1,AG3=1),1,0) -> 1 | AR3: =SUM($AQ$2:AQ3) -> 2 | AS3: =IF(AQ3=1,G3,0) -> 272 | AT3: =IF(AQ3=1,K3,0) -> 5 | AU3: =TRIM(IF(Raw!N3="","weight missing; ","")&IF(Raw!K3="","storage missing; ","")&IF(ISNUMBER(FIND(" و ",Raw!K3)),"dual storage - SSD part used; ","")&IF(ISNUMBER(SEARCH("TB",Raw!K3)),"storage written as TB; ","")&IF(Raw!I3="","cpu missing; ","")&IF(Raw!M3="","gpu missing; ","")&IF(Raw!J3="","ram missing; ","")&IF(Raw!L3="","screen missing; ",""))
A4: =Raw!A4 -> 133524 | B4: =Raw!B4 -> لپ تاپ لنوو 15.3 اینچی مدل IdeaPad Slim 3 i5 13420H 16GB 512GB | C4: =LOWER(TRIM(Raw!C4)) -> lenovo | D4: =IFERROR(INDEX(Params!$B$5:$B$13,MATCH(C4,Params!$A$5:$A$13,0)),PROPER(C4)) -> Lenovo | E4: =IF(Raw!F4,"Available","Out of stock") -> Available | F4: =IF(Raw!D4="","",Raw!D4) -> 185000000 | G4: =IF(ISNUMBER(F4),F4/1000000,"") -> 185 | H4: =IF(Raw!E4="","",Raw!E4) | I4: =IF(AND(ISNUMBER(H4),ISNUMBER(F4)),IF(H4>F4,(H4-F4)/H4,0),0) -> 0 | J4: =IF(I4>0,1,0) -> 0 | K4: =Raw!G4 -> 3.8 | L4: =Raw!H4 -> 36 | M4: =IF(L4>0,(L4*K4+p_m*p_c)/(L4+p_m),"") -> 3.9467391 | N4: =IF(Raw!I4="","",TRIM(Raw!I4)) -> Core i5 13420H | O4: =IF(N4="","Unknown",IF(LEFT(N4,5)="Apple","Apple",IF(LEFT(N4,5)="Ryzen","AMD","Intel"))) -> Intel | P4: =IF(N4="","Unknown",IF(LEFT(N4,5)="Apple","Apple Silicon",IF(LEFT(N4,8)="Ryzen AI","Ryzen AI",TRIM(LEFT(N4,7))))) -> Core i5 | Q4: =IFERROR(VALUE(LEFT(Raw!J4,FIND(" ",Raw!J4)-1)),"") -> 16 | R4: =IF(NOT(ISNUMBER(Q4)),"Unknown",IF(Q4<=8,"≤ 8 GB",IF(Q4<=16,"12–16 GB","20 GB +"))) -> 12–16 GB | S4: =IF(Raw!K4="","",IF(ISNUMBER(FIND(" و ",Raw!K4)),TRIM(MID(Raw!K4,FIND(" و ",Raw!K4)+3,100)),TRIM(Raw!K4))) -> 512 گیگابایت | T4: =IF(S4="","",IFERROR(IFERROR(VALUE(LEFT(S4,FIND(" ",S4)-1)),VALUE(LEFT(S4,LEN(S4)-2)))*IF(OR(ISNUMBER(SEARCH("ترابایت",S4)),ISNUMBER(SEARCH("TB",S4))),1024,1),"")) -> 512 | U4: =IF(NOT(ISNUMBER(T4)),"Unknown",IF(T4<=256,"≤ 256 GB",IF(T4<=512,"512 GB","1 TB +"))) -> 512 GB | V4: =IFERROR(VALUE(SUBSTITUTE(LEFT(Raw!L4,FIND(" ",Raw!L4)-1),".",MID(1/2,2,1))),"") -> 15.3 | W4: =IFERROR(VALUE(SUBSTITUTE(LEFT(Raw!N4,FIND(" ",Raw!N4)-1),".",MID(1/2,2,1))),"") | X4: =IF(Raw!M4="","",TRIM(Raw!M4)) -> Intel UHD Graphics | Y4: =IF(X4="","Unknown",IF(ISNUMBER(SEARCH("nvidia",X4)),"NVIDIA",IF(ISNUMBER(SEARCH("amd",X4)),"AMD",IF(ISNUMBER(SEARCH("apple",X4)),"Apple",IF(ISNUMBER(SEARCH("intel",X4)),"Intel","Other"))))) -> Intel | Z4: =IF(X4="","Unknown",IF(ISNUMBER(SEARCH("RTX",X4))+ISNUMBER(SEARCH("GTX",X4))+ISNUMBER(SEARCH("nvidia",X4))+ISNUMBER(SEARCH("Radeon RX",X4))>0,"Dedicated","Integrated")) -> Integrated | AA4: =IF(ISNUMBER(SEARCH("RTX",X4)),TRIM(MID(X4,SEARCH("RTX",X4),8)),IF(X4="","Unknown",IF(Z4="Dedicated","Dedicated (model n/a)","Integrated"))) -> Integrated | AB4: =IF(ISNUMBER(G4),INDEX(Params!$E$5:$E$9,MATCH(G4,Params!$D$5:$D$9,1)),"Unknown") -> 100–200 M | AC4: =IF(AND(ISNUMBER(G4),ISNUMBER(Q4)),IF(Q4>0,G4/Q4,""),"") -> 11.5625 | AD4: =IF(OR(p_excl=0,ISNUMBER(SEARCH("لپ",B4))),1,0) -> 1 | AE4: =IF(AND(AD4=1,OR(fBrand="All",D4=fBrand),OR(fCPU="All",O4=fCPU),OR(fGPU="All",Z4=fGPU),OR(fTier="All",AB4=fTier),OR(fRAM="All",R4=fRAM)),1,0) -> 1 | AF4: =IF(AND(AE4=1,ISNUMBER(G4)),1,0) -> 1 | AG4: =IF(AND(AE4=1,L4>0),1,0) -> 1 | AH4: =IF(AF4=1,G4,"") -> 185 | AI4: =IF(COUNTIF($D$2:D4,D4)=1,MAX($AI$1:AI3)+1,"") | AJ4: =IF(COUNTIF($P$2:P4,P4)=1,MAX($AJ$1:AJ3)+1,"") -> 3 | AK4: =IF(AG4=1,M4+ROW()/1000000000,"") -> 3.9467391 | AL4: =IF(AND(AE4=1,I4>0),I4+ROW()/1000000000,"") | AM4: =IF(AND(AF4=1,ISNUMBER(W4),Z4="Dedicated"),1,0) -> 0 | AN4: =SUM($AM$2:AM4) -> 1 | AO4: =IF(AND(AF4=1,ISNUMBER(W4),Z4<>"Dedicated"),1,0) -> 0 | AP4: =SUM($AO$2:AO4) -> 1 | AQ4: =IF(AND(AF4=1,AG4=1),1,0) -> 1 | AR4: =SUM($AQ$2:AQ4) -> 3 | AS4: =IF(AQ4=1,G4,0) -> 185 | AT4: =IF(AQ4=1,K4,0) -> 3.8 | AU4: =TRIM(IF(Raw!N4="","weight missing; ","")&IF(Raw!K4="","storage missing; ","")&IF(ISNUMBER(FIND(" و ",Raw!K4)),"dual storage - SSD part used; ","")&IF(ISNUMBER(SEARCH("TB",Raw!K4)),"storage written as TB; ","")&IF(Raw!I4="","cpu missing; ","")&IF(Raw!M4="","gpu missing; ","")&IF(Raw!J4="","ram missing; ","")&IF(Raw!L4="","screen missing; ","")) -> weight missing;
A5: =Raw!A5 -> 61555 | B5: =Raw!B5 -> لپ تاپ ایسوس 14 اینچی مدل Vivobook E410KA Celeron N4500 4GB 256GB 64GB | C5: =LOWER(TRIM(Raw!C5)) -> asus | D5: =IFERROR(INDEX(Params!$B$5:$B$13,MATCH(C5,Params!$A$5:$A$13,0)),PROPER(C5)) -> ASUS | E5: =IF(Raw!F5,"Available","Out of stock") -> Available | F5: =IF(Raw!D5="","",Raw!D5) -> 65500000 | G5: =IF(ISNUMBER(F5),F5/1000000,"") -> 65.5 | H5: =IF(Raw!E5="","",Raw!E5) | I5: =IF(AND(ISNUMBER(H5),ISNUMBER(F5)),IF(H5>F5,(H5-F5)/H5,0),0) -> 0 | J5: =IF(I5>0,1,0) -> 0 | K5: =Raw!G5 -> 4 | L5: =Raw!H5 -> 24 | M5: =IF(L5>0,(L5*K5+p_m*p_c)/(L5+p_m),"") -> 4.1397059 | N5: =IF(Raw!I5="","",TRIM(Raw!I5)) -> Celeron N4500 | O5: =IF(N5="","Unknown",IF(LEFT(N5,5)="Apple","Apple",IF(LEFT(N5,5)="Ryzen","AMD","Intel"))) -> Intel | P5: =IF(N5="","Unknown",IF(LEFT(N5,5)="Apple","Apple Silicon",IF(LEFT(N5,8)="Ryzen AI","Ryzen AI",TRIM(LEFT(N5,7))))) -> Celeron | Q5: =IFERROR(VALUE(LEFT(Raw!J5,FIND(" ",Raw!J5)-1)),"") -> 4 | R5: =IF(NOT(ISNUMBER(Q5)),"Unknown",IF(Q5<=8,"≤ 8 GB",IF(Q5<=16,"12–16 GB","20 GB +"))) -> ≤ 8 GB | S5: =IF(Raw!K5="","",IF(ISNUMBER(FIND(" و ",Raw!K5)),TRIM(MID(Raw!K5,FIND(" و ",Raw!K5)+3,100)),TRIM(Raw!K5))) -> 256 گیگابایت حافظه SSD | T5: =IF(S5="","",IFERROR(IFERROR(VALUE(LEFT(S5,FIND(" ",S5)-1)),VALUE(LEFT(S5,LEN(S5)-2)))*IF(OR(ISNUMBER(SEARCH("ترابایت",S5)),ISNUMBER(SEARCH("TB",S5))),1024,1),"")) -> 256 | U5: =IF(NOT(ISNUMBER(T5)),"Unknown",IF(T5<=256,"≤ 256 GB",IF(T5<=512,"512 GB","1 TB +"))) -> ≤ 256 GB | V5: =IFERROR(VALUE(SUBSTITUTE(LEFT(Raw!L5,FIND(" ",Raw!L5)-1),".",MID(1/2,2,1))),"") -> 14 | W5: =IFERROR(VALUE(SUBSTITUTE(LEFT(Raw!N5,FIND(" ",Raw!N5)-1),".",MID(1/2,2,1))),"") -> 1.3 | X5: =IF(Raw!M5="","",TRIM(Raw!M5)) -> Intel UHD Graphics | Y5: =IF(X5="","Unknown",IF(ISNUMBER(SEARCH("nvidia",X5)),"NVIDIA",IF(ISNUMBER(SEARCH("amd",X5)),"AMD",IF(ISNUMBER(SEARCH("apple",X5)),"Apple",IF(ISNUMBER(SEARCH("intel",X5)),"Intel","Other"))))) -> Intel | Z5: =IF(X5="","Unknown",IF(ISNUMBER(SEARCH("RTX",X5))+ISNUMBER(SEARCH("GTX",X5))+ISNUMBER(SEARCH("nvidia",X5))+ISNUMBER(SEARCH("Radeon RX",X5))>0,"Dedicated","Integrated")) -> Integrated | AA5: =IF(ISNUMBER(SEARCH("RTX",X5)),TRIM(MID(X5,SEARCH("RTX",X5),8)),IF(X5="","Unknown",IF(Z5="Dedicated","Dedicated (model n/a)","Integrated"))) -> Integrated | AB5: =IF(ISNUMBER(G5),INDEX(Params!$E$5:$E$9,MATCH(G5,Params!$D$5:$D$9,1)),"Unknown") -> < 100 M | AC5: =IF(AND(ISNUMBER(G5),ISNUMBER(Q5)),IF(Q5>0,G5/Q5,""),"") -> 16.375 | AD5: =IF(OR(p_excl=0,ISNUMBER(SEARCH("لپ",B5))),1,0) -> 1 | AE5: =IF(AND(AD5=1,OR(fBrand="All",D5=fBrand),OR(fCPU="All",O5=fCPU),OR(fGPU="All",Z5=fGPU),OR(fTier="All",AB5=fTier),OR(fRAM="All",R5=fRAM)),1,0) -> 1 | AF5: =IF(AND(AE5=1,ISNUMBER(G5)),1,0) -> 1 | AG5: =IF(AND(AE5=1,L5>0),1,0) -> 1 | AH5: =IF(AF5=1,G5,"") -> 65.5 | AI5: =IF(COUNTIF($D$2:D5,D5)=1,MAX($AI$1:AI4)+1,"") -> 3 | AJ5: =IF(COUNTIF($P$2:P5,P5)=1,MAX($AJ$1:AJ4)+1,"") -> 4 | AK5: =IF(AG5=1,M5+ROW()/1000000000,"") -> 4.1397059 | AL5: =IF(AND(AE5=1,I5>0),I5+ROW()/1000000000,"") | AM5: =IF(AND(AF5=1,ISNUMBER(W5),Z5="Dedicated"),1,0) -> 0 | AN5: =SUM($AM$2:AM5) -> 1 | AO5: =IF(AND(AF5=1,ISNUMBER(W5),Z5<>"Dedicated"),1,0) -> 1 | AP5: =SUM($AO$2:AO5) -> 2 | AQ5: =IF(AND(AF5=1,AG5=1),1,0) -> 1 | AR5: =SUM($AQ$2:AQ5) -> 4 | AS5: =IF(AQ5=1,G5,0) -> 65.5 | AT5: =IF(AQ5=1,K5,0) -> 4 | AU5: =TRIM(IF(Raw!N5="","weight missing; ","")&IF(Raw!K5="","storage missing; ","")&IF(ISNUMBER(FIND(" و ",Raw!K5)),"dual storage - SSD part used; ","")&IF(ISNUMBER(SEARCH("TB",Raw!K5)),"storage written as TB; ","")&IF(Raw!I5="","cpu missing; ","")&IF(Raw!M5="","gpu missing; ","")&IF(Raw!J5="","ram missing; ","")&IF(Raw!L5="","screen missing; ","")) -> dual storage - SSD part used;
A6: =Raw!A6 -> 239877 | B6: =Raw!B6 -> لپ تاپ اچ پی 15.6 اینچی مدل Victus 15 FA2082WM i5 13420H 16GB 512GB RTX4050 | C6: =LOWER(TRIM(Raw!C6)) -> hp | D6: =IFERROR(INDEX(Params!$B$5:$B$13,MATCH(C6,Params!$A$5:$A$13,0)),PROPER(C6)) -> HP | E6: =IF(Raw!F6,"Available","Out of stock") -> Available | F6: =IF(Raw!D6="","",Raw!D6) -> 275000000 | G6: =IF(ISNUMBER(F6),F6/1000000,"") -> 275 | H6: =IF(Raw!E6="","",Raw!E6) -> 285000000 | I6: =IF(AND(ISNUMBER(H6),ISNUMBER(F6)),IF(H6>F6,(H6-F6)/H6,0),0) -> 0.035087719 | J6: =IF(I6>0,1,0) -> 1 | K6: =Raw!G6 -> 4.2 | L6: =Raw!H6 -> 36 | M6: =IF(L6>0,(L6*K6+p_m*p_c)/(L6+p_m),"") -> 4.2597826 | N6: =IF(Raw!I6="","",TRIM(Raw!I6)) -> Core i5 13420H | O6: =IF(N6="","Unknown",IF(LEFT(N6,5)="Apple","Apple",IF(LEFT(N6,5)="Ryzen","AMD","Intel"))) -> Intel | P6: =IF(N6="","Unknown",IF(LEFT(N6,5)="Apple","Apple Silicon",IF(LEFT(N6,8)="Ryzen AI","Ryzen AI",TRIM(LEFT(N6,7))))) -> Core i5 | Q6: =IFERROR(VALUE(LEFT(Raw!J6,FIND(" ",Raw!J6)-1)),"") -> 16 | R6: =IF(NOT(ISNUMBER(Q6)),"Unknown",IF(Q6<=8,"≤ 8 GB",IF(Q6<=16,"12–16 GB","20 GB +"))) -> 12–16 GB | S6: =IF(Raw!K6="","",IF(ISNUMBER(FIND(" و ",Raw!K6)),TRIM(MID(Raw!K6,FIND(" و ",Raw!K6)+3,100)),TRIM(Raw!K6))) -> 512 گیگابایت | T6: =IF(S6="","",IFERROR(IFERROR(VALUE(LEFT(S6,FIND(" ",S6)-1)),VALUE(LEFT(S6,LEN(S6)-2)))*IF(OR(ISNUMBER(SEARCH("ترابایت",S6)),ISNUMBER(SEARCH("TB",S6))),1024,1),"")) -> 512 | U6: =IF(NOT(ISNUMBER(T6)),"Unknown",IF(T6<=256,"≤ 256 GB",IF(T6<=512,"512 GB","1 TB +"))) -> 512 GB | V6: =IFERROR(VALUE(SUBSTITUTE(LEFT(Raw!L6,FIND(" ",Raw!L6)-1),".",MID(1/2,2,1))),"") -> 15.6 | W6: =IFERROR(VALUE(SUBSTITUTE(LEFT(Raw!N6,FIND(" ",Raw!N6)-1),".",MID(1/2,2,1))),"") -> 2.29 | X6: =IF(Raw!M6="","",TRIM(Raw!M6)) -> NVIDIA GeForce RTX 4050 | Y6: =IF(X6="","Unknown",IF(ISNUMBER(SEARCH("nvidia",X6)),"NVIDIA",IF(ISNUMBER(SEARCH("amd",X6)),"AMD",IF(ISNUMBER(SEARCH("apple",X6)),"Apple",IF(ISNUMBER(SEARCH("intel",X6)),"Intel","Other"))))) -> NVIDIA | Z6: =IF(X6="","Unknown",IF(ISNUMBER(SEARCH("RTX",X6))+ISNUMBER(SEARCH("GTX",X6))+ISNUMBER(SEARCH("nvidia",X6))+ISNUMBER(SEARCH("Radeon RX",X6))>0,"Dedicated","Integrated")) -> Dedicated | AA6: =IF(ISNUMBER(SEARCH("RTX",X6)),TRIM(MID(X6,SEARCH("RTX",X6),8)),IF(X6="","Unknown",IF(Z6="Dedicated","Dedicated (model n/a)","Integrated"))) -> RTX 4050 | AB6: =IF(ISNUMBER(G6),INDEX(Params!$E$5:$E$9,MATCH(G6,Params!$D$5:$D$9,1)),"Unknown") -> 200–300 M | AC6: =IF(AND(ISNUMBER(G6),ISNUMBER(Q6)),IF(Q6>0,G6/Q6,""),"") -> 17.1875 | AD6: =IF(OR(p_excl=0,ISNUMBER(SEARCH("لپ",B6))),1,0) -> 1 | AE6: =IF(AND(AD6=1,OR(fBrand="All",D6=fBrand),OR(fCPU="All",O6=fCPU),OR(fGPU="All",Z6=fGPU),OR(fTier="All",AB6=fTier),OR(fRAM="All",R6=fRAM)),1,0) -> 1 | AF6: =IF(AND(AE6=1,ISNUMBER(G6)),1,0) -> 1 | AG6: =IF(AND(AE6=1,L6>0),1,0) -> 1 | AH6: =IF(AF6=1,G6,"") -> 275 | AI6: =IF(COUNTIF($D$2:D6,D6)=1,MAX($AI$1:AI5)+1,"") -> 4 | AJ6: =IF(COUNTIF($P$2:P6,P6)=1,MAX($AJ$1:AJ5)+1,"") | AK6: =IF(AG6=1,M6+ROW()/1000000000,"") -> 4.2597826 | AL6: =IF(AND(AE6=1,I6>0),I6+ROW()/1000000000,"") -> 0.035087725 | AM6: =IF(AND(AF6=1,ISNUMBER(W6),Z6="Dedicated"),1,0) -> 1 | AN6: =SUM($AM$2:AM6) -> 2 | AO6: =IF(AND(AF6=1,ISNUMBER(W6),Z6<>"Dedicated"),1,0) -> 0 | AP6: =SUM($AO$2:AO6) -> 2 | AQ6: =IF(AND(AF6=1,AG6=1),1,0) -> 1 | AR6: =SUM($AQ$2:AQ6) -> 5 | AS6: =IF(AQ6=1,G6,0) -> 275 | AT6: =IF(AQ6=1,K6,0) -> 4.2 | AU6: =TRIM(IF(Raw!N6="","weight missing; ","")&IF(Raw!K6="","storage missing; ","")&IF(ISNUMBER(FIND(" و ",Raw!K6)),"dual storage - SSD part used; ","")&IF(ISNUMBER(SEARCH("TB",Raw!K6)),"storage written as TB; ","")&IF(Raw!I6="","cpu missing; ","")&IF(Raw!M6="","gpu missing; ","")&IF(Raw!J6="","ram missing; ","")&IF(Raw!L6="","screen missing; ",""))
A7: =Raw!A7 -> 134276 | B7: =Raw!B7 -> لپ تاپ 15.6 اینچی اچ پی مدل Victus 15 FA2013DX i5 13420H 16GB 512GB RTX 3050 | C7: =LOWER(TRIM(Raw!C7)) -> hp | D7: =IFERROR(INDEX(Params!$B$5:$B$13,MATCH(C7,Params!$A$5:$A$13,0)),PROPER(C7)) -> HP | E7: =IF(Raw!F7,"Available","Out of stock") -> Available | F7: =IF(Raw!D7="","",Raw!D7) -> 242000000 | G7: =IF(ISNUMBER(F7),F7/1000000,"") -> 242 | H7: =IF(Raw!E7="","",Raw!E7) | I7: =IF(AND(ISNUMBER(H7),ISNUMBER(F7)),IF(H7>F7,(H7-F7)/H7,0),0) -> 0 | J7: =IF(I7>0,1,0) -> 0 | K7: =Raw!G7 -> 4.4 | L7: =Raw!H7 -> 32 | M7: =IF(L7>0,(L7*K7+p_m*p_c)/(L7+p_m),"") -> 4.4178571 | N7: =IF(Raw!I7="","",TRIM(Raw!I7)) -> Core i5 13420H | O7: =IF(N7="","Unknown",IF(LEFT(N7,5)="Apple","Apple",IF(LEFT(N7,5)="Ryzen","AMD","Intel"))) -> Intel | P7: =IF(N7="","Unknown",IF(LEFT(N7,5)="Apple","Apple Silicon",IF(LEFT(N7,8)="Ryzen AI","Ryzen AI",TRIM(LEFT(N7,7))))) -> Core i5 | Q7: =IFERROR(VALUE(LEFT(Raw!J7,FIND(" ",Raw!J7)-1)),"") -> 16 | R7: =IF(NOT(ISNUMBER(Q7)),"Unknown",IF(Q7<=8,"≤ 8 GB",IF(Q7<=16,"12–16 GB","20 GB +"))) -> 12–16 GB | S7: =IF(Raw!K7="","",IF(ISNUMBER(FIND(" و ",Raw!K7)),TRIM(MID(Raw!K7,FIND(" و ",Raw!K7)+3,100)),TRIM(Raw!K7))) -> 512 گیگابایت | T7: =IF(S7="","",IFERROR(IFERROR(VALUE(LEFT(S7,FIND(" ",S7)-1)),VALUE(LEFT(S7,LEN(S7)-2)))*IF(OR(ISNUMBER(SEARCH("ترابایت",S7)),ISNUMBER(SEARCH("TB",S7))),1024,1),"")) -> 512 | U7: =IF(NOT(ISNUMBER(T7)),"Unknown",IF(T7<=256,"≤ 256 GB",IF(T7<=512,"512 GB","1 TB +"))) -> 512 GB | V7: =IFERROR(VALUE(SUBSTITUTE(LEFT(Raw!L7,FIND(" ",Raw!L7)-1),".",MID(1/2,2,1))),"") -> 15.6 | W7: =IFERROR(VALUE(SUBSTITUTE(LEFT(Raw!N7,FIND(" ",Raw!N7)-1),".",MID(1/2,2,1))),"") -> 2.2 | X7: =IF(Raw!M7="","",TRIM(Raw!M7)) -> NVIDIA GeForce RTX 3050 | Y7: =IF(X7="","Unknown",IF(ISNUMBER(SEARCH("nvidia",X7)),"NVIDIA",IF(ISNUMBER(SEARCH("amd",X7)),"AMD",IF(ISNUMBER(SEARCH("apple",X7)),"Apple",IF(ISNUMBER(SEARCH("intel",X7)),"Intel","Other"))))) -> NVIDIA | Z7: =IF(X7="","Unknown",IF(ISNUMBER(SEARCH("RTX",X7))+ISNUMBER(SEARCH("GTX",X7))+ISNUMBER(SEARCH("nvidia",X7))+ISNUMBER(SEARCH("Radeon RX",X7))>0,"Dedicated","Integrated")) -> Dedicated | AA7: =IF(ISNUMBER(SEARCH("RTX",X7)),TRIM(MID(X7,SEARCH("RTX",X7),8)),IF(X7="","Unknown",IF(Z7="Dedicated","Dedicated (model n/a)","Integrated"))) -> RTX 3050 | AB7: =IF(ISNUMBER(G7),INDEX(Params!$E$5:$E$9,MATCH(G7,Params!$D$5:$D$9,1)),"Unknown") -> 200–300 M | AC7: =IF(AND(ISNUMBER(G7),ISNUMBER(Q7)),IF(Q7>0,G7/Q7,""),"") -> 15.125 | AD7: =IF(OR(p_excl=0,ISNUMBER(SEARCH("لپ",B7))),1,0) -> 1 | AE7: =IF(AND(AD7=1,OR(fBrand="All",D7=fBrand),OR(fCPU="All",O7=fCPU),OR(fGPU="All",Z7=fGPU),OR(fTier="All",AB7=fTier),OR(fRAM="All",R7=fRAM)),1,0) -> 1 | AF7: =IF(AND(AE7=1,ISNUMBER(G7)),1,0) -> 1 | AG7: =IF(AND(AE7=1,L7>0),1,0) -> 1 | AH7: =IF(AF7=1,G7,"") -> 242 | AI7: =IF(COUNTIF($D$2:D7,D7)=1,MAX($AI$1:AI6)+1,"") | AJ7: =IF(COUNTIF($P$2:P7,P7)=1,MAX($AJ$1:AJ6)+1,"") | AK7: =IF(AG7=1,M7+ROW()/1000000000,"") -> 4.4178571 | AL7: =IF(AND(AE7=1,I7>0),I7+ROW()/1000000000,"") | AM7: =IF(AND(AF7=1,ISNUMBER(W7),Z7="Dedicated"),1,0) -> 1 | AN7: =SUM($AM$2:AM7) -> 3 | AO7: =IF(AND(AF7=1,ISNUMBER(W7),Z7<>"Dedicated"),1,0) -> 0 | AP7: =SUM($AO$2:AO7) -> 2 | AQ7: =IF(AND(AF7=1,AG7=1),1,0) -> 1 | AR7: =SUM($AQ$2:AQ7) -> 6 | AS7: =IF(AQ7=1,G7,0) -> 242 | AT7: =IF(AQ7=1,K7,0) -> 4.4 | AU7: =TRIM(IF(Raw!N7="","weight missing; ","")&IF(Raw!K7="","storage missing; ","")&IF(ISNUMBER(FIND(" و ",Raw!K7)),"dual storage - SSD part used; ","")&IF(ISNUMBER(SEARCH("TB",Raw!K7)),"storage written as TB; ","")&IF(Raw!I7="","cpu missing; ","")&IF(Raw!M7="","gpu missing; ","")&IF(Raw!J7="","ram missing; ","")&IF(Raw!L7="","screen missing; ",""))
A8: =Raw!A8 -> 133168 | B8: =Raw!B8 -> لپ تاپ لنوو 15.3 اینچی مدل IdeaPad Slim 3 i7 13620H 16GB 512GB | C8: =LOWER(TRIM(Raw!C8)) -> lenovo | D8: =IFERROR(INDEX(Params!$B$5:$B$13,MATCH(C8,Params!$A$5:$A$13,0)),PROPER(C8)) -> Lenovo | E8: =IF(Raw!F8,"Available","Out of stock") -> Available | F8: =IF(Raw!D8="","",Raw!D8) -> 220200000 | G8: =IF(ISNUMBER(F8),F8/1000000,"") -> 220.2 | H8: =IF(Raw!E8="","",Raw!E8) | I8: =IF(AND(ISNUMBER(H8),ISNUMBER(F8)),IF(H8>F8,(H8-F8)/H8,0),0) -> 0 | J8: =IF(I8>0,1,0) -> 0 | K8: =Raw!G8 -> 3.2 | L8: =Raw!H8 -> 11 | M8: =IF(L8>0,(L8*K8+p_m*p_c)/(L8+p_m),"") -> 3.8071429 | N8: =IF(Raw!I8="","",TRIM(Raw!I8)) -> Core i7 13620H | O8: =IF(N8="","Unknown",IF(LEFT(N8,5)="Apple","Apple",IF(LEFT(N8,5)="Ryzen","AMD","Intel"))) -> Intel | P8: =IF(N8="","Unknown",IF(LEFT(N8,5)="Apple","Apple Silicon",IF(LEFT(N8,8)="Ryzen AI","Ryzen AI",TRIM(LEFT(N8,7))))) -> Core i7 | Q8: =IFERROR(VALUE(LEFT(Raw!J8,FIND(" ",Raw!J8)-1)),"") -> 16 | R8: =IF(NOT(ISNUMBER(Q8)),"Unknown",IF(Q8<=8,"≤ 8 GB",IF(Q8<=16,"12–16 GB","20 GB +"))) -> 12–16 GB | S8: =IF(Raw!K8="","",IF(ISNUMBER(FIND(" و ",Raw!K8)),TRIM(MID(Raw!K8,FIND(" و ",Raw!K8)+3,100)),TRIM(Raw!K8))) -> 512 گیگابایت | T8: =IF(S8="","",IFERROR(IFERROR(VALUE(LEFT(S8,FIND(" ",S8)-1)),VALUE(LEFT(S8,LEN(S8)-2)))*IF(OR(ISNUMBER(SEARCH("ترابایت",S8)),ISNUMBER(SEARCH("TB",S8))),1024,1),"")) -> 512 | U8: =IF(NOT(ISNUMBER(T8)),"Unknown",IF(T8<=256,"≤ 256 GB",IF(T8<=512,"512 GB","1 TB +"))) -> 512 GB | V8: =IFERROR(VALUE(SUBSTITUTE(LEFT(Raw!L8,FIND(" ",Raw!L8)-1),".",MID(1/2,2,1))),"") -> 15.3 | W8: =IFERROR(VALUE(SUBSTITUTE(LEFT(Raw!N8,FIND(" ",Raw!N8)-1),".",MID(1/2,2,1))),"") | X8: =IF(Raw!M8="","",TRIM(Raw!M8)) -> Intel UHD Graphics | Y8: =IF(X8="","Unknown",IF(ISNUMBER(SEARCH("nvidia",X8)),"NVIDIA",IF(ISNUMBER(SEARCH("amd",X8)),"AMD",IF(ISNUMBER(SEARCH("apple",X8)),"Apple",IF(ISNUMBER(SEARCH("intel",X8)),"Intel","Other"))))) -> Intel | Z8: =IF(X8="","Unknown",IF(ISNUMBER(SEARCH("RTX",X8))+ISNUMBER(SEARCH("GTX",X8))+ISNUMBER(SEARCH("nvidia",X8))+ISNUMBER(SEARCH("Radeon RX",X8))>0,"Dedicated","Integrated")) -> Integrated | AA8: =IF(ISNUMBER(SEARCH("RTX",X8)),TRIM(MID(X8,SEARCH("RTX",X8),8)),IF(X8="","Unknown",IF(Z8="Dedicated","Dedicated (model n/a)","Integrated"))) -> Integrated | AB8: =IF(ISNUMBER(G8),INDEX(Params!$E$5:$E$9,MATCH(G8,Params!$D$5:$D$9,1)),"Unknown") -> 200–300 M | AC8: =IF(AND(ISNUMBER(G8),ISNUMBER(Q8)),IF(Q8>0,G8/Q8,""),"") -> 13.7625 | AD8: =IF(OR(p_excl=0,ISNUMBER(SEARCH("لپ",B8))),1,0) -> 1 | AE8: =IF(AND(AD8=1,OR(fBrand="All",D8=fBrand),OR(fCPU="All",O8=fCPU),OR(fGPU="All",Z8=fGPU),OR(fTier="All",AB8=fTier),OR(fRAM="All",R8=fRAM)),1,0) -> 1 | AF8: =IF(AND(AE8=1,ISNUMBER(G8)),1,0) -> 1 | AG8: =IF(AND(AE8=1,L8>0),1,0) -> 1 | AH8: =IF(AF8=1,G8,"") -> 220.2 | AI8: =IF(COUNTIF($D$2:D8,D8)=1,MAX($AI$1:AI7)+1,"") | AJ8: =IF(COUNTIF($P$2:P8,P8)=1,MAX($AJ$1:AJ7)+1,"") | AK8: =IF(AG8=1,M8+ROW()/1000000000,"") -> 3.8071429 | AL8: =IF(AND(AE8=1,I8>0),I8+ROW()/1000000000,"") | AM8: =IF(AND(AF8=1,ISNUMBER(W8),Z8="Dedicated"),1,0) -> 0 | AN8: =SUM($AM$2:AM8) -> 3 | AO8: =IF(AND(AF8=1,ISNUMBER(W8),Z8<>"Dedicated"),1,0) -> 0 | AP8: =SUM($AO$2:AO8) -> 2 | AQ8: =IF(AND(AF8=1,AG8=1),1,0) -> 1 | AR8: =SUM($AQ$2:AQ8) -> 7 | AS8: =IF(AQ8=1,G8,0) -> 220.2 | AT8: =IF(AQ8=1,K8,0) -> 3.2 | AU8: =TRIM(IF(Raw!N8="","weight missing; ","")&IF(Raw!K8="","storage missing; ","")&IF(ISNUMBER(FIND(" و ",Raw!K8)),"dual storage - SSD part used; ","")&IF(ISNUMBER(SEARCH("TB",Raw!K8)),"storage written as TB; ","")&IF(Raw!I8="","cpu missing; ","")&IF(Raw!M8="","gpu missing; ","")&IF(Raw!J8="","ram missing; ","")&IF(Raw!L8="","screen missing; ","")) -> weight missing;
A9: =Raw!A9 -> 106793 | B9: =Raw!B9 -> لپ تاپ 15.6 اینچی لنوو مدل IdeaPad 1 15IJL7 Celeron N4500 8GB 256GB | C9: =LOWER(TRIM(Raw!C9)) -> lenovo | D9: =IFERROR(INDEX(Params!$B$5:$B$13,MATCH(C9,Params!$A$5:$A$13,0)),PROPER(C9)) -> Lenovo | E9: =IF(Raw!F9,"Available","Out of stock") -> Available | F9: =IF(Raw!D9="","",Raw!D9) -> 94500000 | G9: =IF(ISNUMBER(F9),F9/1000000,"") -> 94.5 | H9: =IF(Raw!E9="","",Raw!E9) | I9: =IF(AND(ISNUMBER(H9),ISNUMBER(F9)),IF(H9>F9,(H9-F9)/H9,0),0) -> 0 | J9: =IF(I9>0,1,0) -> 0 | K9: =Raw!G9 -> 4.7 | L9: =Raw!H9 -> 6 | M9: =IF(L9>0,(L9*K9+p_m*p_c)/(L9+p_m),"") -> 4.559375 | N9: =IF(Raw!I9="","",TRIM(Raw!I9)) -> Celeron N4500 | O9: =IF(N9="","Unknown",IF(LEFT(N9,5)="Apple","Apple",IF(LEFT(N9,5)="Ryzen","AMD","Intel"))) -> Intel | P9: =IF(N9="","Unknown",IF(LEFT(N9,5)="Apple","Apple Silicon",IF(LEFT(N9,8)="Ryzen AI","Ryzen AI",TRIM(LEFT(N9,7))))) -> Celeron | Q9: =IFERROR(VALUE(LEFT(Raw!J9,FIND(" ",Raw!J9)-1)),"") -> 8 | R9: =IF(NOT(ISNUMBER(Q9)),"Unknown",IF(Q9<=8,"≤ 8 GB",IF(Q9<=16,"12–16 GB","20 GB +"))) -> ≤ 8 GB | S9: =IF(Raw!K9="","",IF(ISNUMBER(FIND(" و ",Raw!K9)),TRIM(MID(Raw!K9,FIND(" و ",Raw!K9)+3,100)),TRIM(Raw!K9))) -> 256 گیگابایت | T9: =IF(S9="","",IFERROR(IFERROR(VALUE(LEFT(S9,FIND(" ",S9)-1)),VALUE(LEFT(S9,LEN(S9)-2)))*IF(OR(ISNUMBER(SEARCH("ترابایت",S9)),ISNUMBER(SEARCH("TB",S9))),1024,1),"")) -> 256 | U9: =IF(NOT(ISNUMBER(T9)),"Unknown",IF(T9<=256,"≤ 256 GB",IF(T9<=512,"512 GB","1 TB +"))) -> ≤ 256 GB | V9: =IFERROR(VALUE(SUBSTITUTE(LEFT(Raw!L9,FIND(" ",Raw!L9)-1),".",MID(1/2,2,1))),"") -> 15.6 | W9: =IFERROR(VALUE(SUBSTITUTE(LEFT(Raw!N9,FIND(" ",Raw!N9)-1),".",MID(1/2,2,1))),"") -> 1.55 | X9: =IF(Raw!M9="","",TRIM(Raw!M9)) -> Intel UHD Graphics | Y9: =IF(X9="","Unknown",IF(ISNUMBER(SEARCH("nvidia",X9)),"NVIDIA",IF(ISNUMBER(SEARCH("amd",X9)),"AMD",IF(ISNUMBER(SEARCH("apple",X9)),"Apple",IF(ISNUMBER(SEARCH("intel",X9)),"Intel","Other"))))) -> Intel | Z9: =IF(X9="","Unknown",IF(ISNUMBER(SEARCH("RTX",X9))+ISNUMBER(SEARCH("GTX",X9))+ISNUMBER(SEARCH("nvidia",X9))+ISNUMBER(SEARCH("Radeon RX",X9))>0,"Dedicated","Integrated")) -> Integrated | AA9: =IF(ISNUMBER(SEARCH("RTX",X9)),TRIM(MID(X9,SEARCH("RTX",X9),8)),IF(X9="","Unknown",IF(Z9="Dedicated","Dedicated (model n/a)","Integrated"))) -> Integrated | AB9: =IF(ISNUMBER(G9),INDEX(Params!$E$5:$E$9,MATCH(G9,Params!$D$5:$D$9,1)),"Unknown") -> < 100 M | AC9: =IF(AND(ISNUMBER(G9),ISNUMBER(Q9)),IF(Q9>0,G9/Q9,""),"") -> 11.8125 | AD9: =IF(OR(p_excl=0,ISNUMBER(SEARCH("لپ",B9))),1,0) -> 1 | AE9: =IF(AND(AD9=1,OR(fBrand="All",D9=fBrand),OR(fCPU="All",O9=fCPU),OR(fGPU="All",Z9=fGPU),OR(fTier="All",AB9=fTier),OR(fRAM="All",R9=fRAM)),1,0) -> 1 | AF9: =IF(AND(AE9=1,ISNUMBER(G9)),1,0) -> 1 | AG9: =IF(AND(AE9=1,L9>0),1,0) -> 1 | AH9: =IF(AF9=1,G9,"") -> 94.5 | AI9: =IF(COUNTIF($D$2:D9,D9)=1,MAX($AI$1:AI8)+1,"") | AJ9: =IF(COUNTIF($P$2:P9,P9)=1,MAX($AJ$1:AJ8)+1,"") | AK9: =IF(AG9=1,M9+ROW()/1000000000,"") -> 4.559375 | AL9: =IF(AND(AE9=1,I9>0),I9+ROW()/1000000000,"") | AM9: =IF(AND(AF9=1,ISNUMBER(W9),Z9="Dedicated"),1,0) -> 0 | AN9: =SUM($AM$2:AM9) -> 3 | AO9: =IF(AND(AF9=1,ISNUMBER(W9),Z9<>"Dedicated"),1,0) -> 1 | AP9: =SUM($AO$2:AO9) -> 3 | AQ9: =IF(AND(AF9=1,AG9=1),1,0) -> 1 | AR9: =SUM($AQ$2:AQ9) -> 8 | AS9: =IF(AQ9=1,G9,0) -> 94.5 | AT9: =IF(AQ9=1,K9,0) -> 4.7 | AU9: =TRIM(IF(Raw!N9="","weight missing; ","")&IF(Raw!K9="","storage missing; ","")&IF(ISNUMBER(FIND(" و ",Raw!K9)),"dual storage - SSD part used; ","")&IF(ISNUMBER(SEARCH("TB",Raw!K9)),"storage written as TB; ","")&IF(Raw!I9="","cpu missing; ","")&IF(Raw!M9="","gpu missing; ","")&IF(Raw!J9="","ram missing; ","")&IF(Raw!L9="","screen missing; ",""))
A10: =Raw!A10 -> 66798 | B10: =Raw!B10 -> لپ تاپ ایسوس 15.6 اینچی مدل Vivobook X1504VA Core 7 ۱۵۰U 16GB 512GB | C10: =LOWER(TRIM(Raw!C10)) -> asus | D10: =IFERROR(INDEX(Params!$B$5:$B$13,MATCH(C10,Params!$A$5:$A$13,0)),PROPER(C10)) -> ASUS | E10: =IF(Raw!F10,"Available","Out of stock") -> Available | F10: =IF(Raw!D10="","",Raw!D10) -> 196600000 | G10: =IF(ISNUMBER(F10),F10/1000000,"") -> 196.6 | H10: =IF(Raw!E10="","",Raw!E10) | I10: =IF(AND(ISNUMBER(H10),ISNUMBER(F10)),IF(H10>F10,(H10-F10)/H10,0),0) -> 0 | J10: =IF(I10>0,1,0) -> 0 | K10: =Raw!G10 -> 5 | L10: =Raw!H10 -> 1 | M10: =IF(L10>0,(L10*K10+p_m*p_c)/(L10+p_m),"") -> 4.5227273 | N10: =IF(Raw!I10="","",TRIM(Raw!I10)) -> Core 7 150U | O10: =IF(N10="","Unknown",IF(LEFT(N10,5)="Apple","Apple",IF(LEFT(N10,5)="Ryzen","AMD","Intel"))) -> Intel | P10: =IF(N10="","Unknown",IF(LEFT(N10,5)="Apple","Apple Silicon",IF(LEFT(N10,8)="Ryzen AI","Ryzen AI",TRIM(LEFT(N10,7))))) -> Core 7 | Q10: =IFERROR(VALUE(LEFT(Raw!J10,FIND(" ",Raw!J10)-1)),"") -> 16 | R10: =IF(NOT(ISNUMBER(Q10)),"Unknown",IF(Q10<=8,"≤ 8 GB",IF(Q10<=16,"12–16 GB","20 GB +"))) -> 12–16 GB | S10: =IF(Raw!K10="","",IF(ISNUMBER(FIND(" و ",Raw!K10)),TRIM(MID(Raw!K10,FIND(" و ",Raw!K10)+3,100)),TRIM(Raw!K10))) -> 512 گیگابایت | T10: =IF(S10="","",IFERROR(IFERROR(VALUE(LEFT(S10,FIND(" ",S10)-1)),VALUE(LEFT(S10,LEN(S10)-2)))*IF(OR(ISNUMBER(SEARCH("ترابایت",S10)),ISNUMBER(SEARCH("TB",S10))),1024,1),"")) -> 512 | U10: =IF(NOT(ISNUMBER(T10)),"Unknown",IF(T10<=256,"≤ 256 GB",IF(T10<=512,"512 GB","1 TB +"))) -> 512 GB | V10: =IFERROR(VALUE(SUBSTITUTE(LEFT(Raw!L10,FIND(" ",Raw!L10)-1),".",MID(1/2,2,1))),"") -> 15.6 | W10: =IFERROR(VALUE(SUBSTITUTE(LEFT(Raw!N10,FIND(" ",Raw!N10)-1),".",MID(1/2,2,1))),"") -> 1.7 | X10: =IF(Raw!M10="","",TRIM(Raw!M10)) -> Intel | Y10: =IF(X10="","Unknown",IF(ISNUMBER(SEARCH("nvidia",X10)),"NVIDIA",IF(ISNUMBER(SEARCH("amd",X10)),"AMD",IF(ISNUMBER(SEARCH("apple",X10)),"Apple",IF(ISNUMBER(SEARCH("intel",X10)),"Intel","Other"))))) -> Intel | Z10: =IF(X10="","Unknown",IF(ISNUMBER(SEARCH("RTX",X10))+ISNUMBER(SEARCH("GTX",X10))+ISNUMBER(SEARCH("nvidia",X10))+ISNUMBER(SEARCH("Radeon RX",X10))>0,"Dedicated","Integrated")) -> Integrated | AA10: =IF(ISNUMBER(SEARCH("RTX",X10)),TRIM(MID(X10,SEARCH("RTX",X10),8)),IF(X10="","Unknown",IF(Z10="Dedicated","Dedicated (model n/a)","Integrated"))) -> Integrated | AB10: =IF(ISNUMBER(G10),INDEX(Params!$E$5:$E$9,MATCH(G10,Params!$D$5:$D$9,1)),"Unknown") -> 100–200 M | AC10: =IF(AND(ISNUMBER(G10),ISNUMBER(Q10)),IF(Q10>0,G10/Q10,""),"") -> 12.2875 | AD10: =IF(OR(p_excl=0,ISNUMBER(SEARCH("لپ",B10))),1,0) -> 1 | AE10: =IF(AND(AD10=1,OR(fBrand="All",D10=fBrand),OR(fCPU="All",O10=fCPU),OR(fGPU="All",Z10=fGPU),OR(fTier="All",AB10=fTier),OR(fRAM="All",R10=fRAM)),1,0) -> 1 | AF10: =IF(AND(AE10=1,ISNUMBER(G10)),1,0) -> 1 | AG10: =IF(AND(AE10=1,L10>0),1,0) -> 1 | AH10: =IF(AF10=1,G10,"") -> 196.6 | AI10: =IF(COUNTIF($D$2:D10,D10)=1,MAX($AI$1:AI9)+1,"") | AJ10: =IF(COUNTIF($P$2:P10,P10)=1,MAX($AJ$1:AJ9)+1,"") -> 5 | AK10: =IF(AG10=1,M10+ROW()/1000000000,"") -> 4.5227273 | AL10: =IF(AND(AE10=1,I10>0),I10+ROW()/1000000000,"") | AM10: =IF(AND(AF10=1,ISNUMBER(W10),Z10="Dedicated"),1,0) -> 0 | AN10: =SUM($AM$2:AM10) -> 3 | AO10: =IF(AND(AF10=1,ISNUMBER(W10),Z10<>"Dedicated"),1,0) -> 1 | AP10: =SUM($AO$2:AO10) -> 4 | AQ10: =IF(AND(AF10=1,AG10=1),1,0) -> 1 | AR10: =SUM($AQ$2:AQ10) -> 9 | AS10: =IF(AQ10=1,G10,0) -> 196.6 | AT10: =IF(AQ10=1,K10,0) -> 5 | AU10: =TRIM(IF(Raw!N10="","weight missing; ","")&IF(Raw!K10="","storage missing; ","")&IF(ISNUMBER(FIND(" و ",Raw!K10)),"dual storage - SSD part used; ","")&IF(ISNUMBER(SEARCH("TB",Raw!K10)),"storage written as TB; ","")&IF(Raw!I10="","cpu missing; ","")&IF(Raw!M10="","gpu missing; ","")&IF(Raw!J10="","ram missing; ","")&IF(Raw!L10="","screen missing; ",""))
A11: =Raw!A11 -> 49420 | B11: =Raw!B11 -> لپ تاپ لنوو 15.6 اینچی مدل V15 G4 i5 13420H 16GB 512GB SSD | C11: =LOWER(TRIM(Raw!C11)) -> lenovo | D11: =IFERROR(INDEX(Params!$B$5:$B$13,MATCH(C11,Params!$A$5:$A$13,0)),PROPER(C11)) -> Lenovo | E11: =IF(Raw!F11,"Available","Out of stock") -> Available | F11: =IF(Raw!D11="","",Raw!D11) -> 178000000 | G11: =IF(ISNUMBER(F11),F11/1000000,"") -> 178 | H11: =IF(Raw!E11="","",Raw!E11) | I11: =IF(AND(ISNUMBER(H11),ISNUMBER(F11)),IF(H11>F11,(H11-F11)/H11,0),0) -> 0 | J11: =IF(I11>0,1,0) -> 0 | K11: =Raw!G11 -> 4.1 | L11: =Raw!H11 -> 36 | M11: =IF(L11>0,(L11*K11+p_m*p_c)/(L11+p_m),"") -> 4.1815217 | N11: =IF(Raw!I11="","",TRIM(Raw!I11)) -> Core i5 13420H | O11: =IF(N11="","Unknown",IF(LEFT(N11,5)="Apple","Apple",IF(LEFT(N11,5)="Ryzen","AMD","Intel"))) -> Intel | P11: =IF(N11="","Unknown",IF(LEFT(N11,5)="Apple","Apple Silicon",IF(LEFT(N11,8)="Ryzen AI","Ryzen AI",TRIM(LEFT(N11,7))))) -> Core i5 | Q11: =IFERROR(VALUE(LEFT(Raw!J11,FIND(" ",Raw!J11)-1)),"") -> 16 | R11: =IF(NOT(ISNUMBER(Q11)),"Unknown",IF(Q11<=8,"≤ 8 GB",IF(Q11<=16,"12–16 GB","20 GB +"))) -> 12–16 GB | S11: =IF(Raw!K11="","",IF(ISNUMBER(FIND(" و ",Raw!K11)),TRIM(MID(Raw!K11,FIND(" و ",Raw!K11)+3,100)),TRIM(Raw!K11))) -> 512 گیگابایت | T11: =IF(S11="","",IFERROR(IFERROR(VALUE(LEFT(S11,FIND(" ",S11)-1)),VALUE(LEFT(S11,LEN(S11)-2)))*IF(OR(ISNUMBER(SEARCH("ترابایت",S11)),ISNUMBER(SEARCH("TB",S11))),1024,1),"")) -> 512 | U11: =IF(NOT(ISNUMBER(T11)),"Unknown",IF(T11<=256,"≤ 256 GB",IF(T11<=512,"512 GB","1 TB +"))) -> 512 GB | V11: =IFERROR(VALUE(SUBSTITUTE(LEFT(Raw!L11,FIND(" ",Raw!L11)-1),".",MID(1/2,2,1))),"") -> 15.6 | W11: =IFERROR(VALUE(SUBSTITUTE(LEFT(Raw!N11,FIND(" ",Raw!N11)-1),".",MID(1/2,2,1))),"") -> 1.6 | X11: =IF(Raw!M11="","",TRIM(Raw!M11)) -> Intel UHD Graphics | Y11: =IF(X11="","Unknown",IF(ISNUMBER(SEARCH("nvidia",X11)),"NVIDIA",IF(ISNUMBER(SEARCH("amd",X11)),"AMD",IF(ISNUMBER(SEARCH("apple",X11)),"Apple",IF(ISNUMBER(SEARCH("intel",X11)),"Intel","Other"))))) -> Intel | Z11: =IF(X11="","Unknown",IF(ISNUMBER(SEARCH("RTX",X11))+ISNUMBER(SEARCH("GTX",X11))+ISNUMBER(SEARCH("nvidia",X11))+ISNUMBER(SEARCH("Radeon RX",X11))>0,"Dedicated","Integrated")) -> Integrated | AA11: =IF(ISNUMBER(SEARCH("RTX",X11)),TRIM(MID(X11,SEARCH("RTX",X11),8)),IF(X11="","Unknown",IF(Z11="Dedicated","Dedicated (model n/a)","Integrated"))) -> Integrated | AB11: =IF(ISNUMBER(G11),INDEX(Params!$E$5:$E$9,MATCH(G11,Params!$D$5:$D$9,1)),"Unknown") -> 100–200 M | AC11: =IF(AND(ISNUMBER(G11),ISNUMBER(Q11)),IF(Q11>0,G11/Q11,""),"") -> 11.125 | AD11: =IF(OR(p_excl=0,ISNUMBER(SEARCH("لپ",B11))),1,0) -> 1 | AE11: =IF(AND(AD11=1,OR(fBrand="All",D11=fBrand),OR(fCPU="All",O11=fCPU),OR(fGPU="All",Z11=fGPU),OR(fTier="All",AB11=fTier),OR(fRAM="All",R11=fRAM)),1,0) -> 1 | AF11: =IF(AND(AE11=1,ISNUMBER(G11)),1,0) -> 1 | AG11: =IF(AND(AE11=1,L11>0),1,0) -> 1 | AH11: =IF(AF11=1,G11,"") -> 178 | AI11: =IF(COUNTIF($D$2:D11,D11)=1,MAX($AI$1:AI10)+1,"") | AJ11: =IF(COUNTIF($P$2:P11,P11)=1,MAX($AJ$1:AJ10)+1,"") | AK11: =IF(AG11=1,M11+ROW()/1000000000,"") -> 4.1815218 | AL11: =IF(AND(AE11=1,I11>0),I11+ROW()/1000000000,"") | AM11: =IF(AND(AF11=1,ISNUMBER(W11),Z11="Dedicated"),1,0) -> 0 | AN11: =SUM($AM$2:AM11) -> 3 | AO11: =IF(AND(AF11=1,ISNUMBER(W11),Z11<>"Dedicated"),1,0) -> 1 | AP11: =SUM($AO$2:AO11) -> 5 | AQ11: =IF(AND(AF11=1,AG11=1),1,0) -> 1 | AR11: =SUM($AQ$2:AQ11) -> 10 | AS11: =IF(AQ11=1,G11,0) -> 178 | AT11: =IF(AQ11=1,K11,0) -> 4.1 | AU11: =TRIM(IF(Raw!N11="","weight missing; ","")&IF(Raw!K11="","storage missing; ","")&IF(ISNUMBER(FIND(" و ",Raw!K11)),"dual storage - SSD part used; ","")&IF(ISNUMBER(SEARCH("TB",Raw!K11)),"storage written as TB; ","")&IF(Raw!I11="","cpu missing; ","")&IF(Raw!M11="","gpu missing; ","")&IF(Raw!J11="","ram missing; ","")&IF(Raw!L11="","screen missing; ",""))
